Workbook
Name AA: #REF!
Name AA: #REF!
Name AA: #REF!
Name AA: #REF!
Name ASDF: #REF!
Name ASDF: #REF!
Name ASDF: #REF!
Name ASDF: #REF!
Name BB: #REF!
Name BB: #REF!
Name BB: #REF!
Name BB: #REF!
Name CAR_RAIL: #REF!
Name CAR_RAIL: #REF!
Name CAR_RAIL: #REF!
Name CAR_RAIL: #REF!
Name CAR_슈간격: #REF!
Name CAR_슈간격: #REF!
Name CAR_슈간격: #REF!
Name CAR_슈간격: #REF!
Name CAR_오메가: #REF!
Name CAR_오메가: #REF!
Name CAR_오메가: #REF!
Name CAR_오메가: #REF!
Name CARRAIL_A: #REF!
Name CARRAIL_A: #REF!
Name CARRAIL_A: #REF!
Name CARRAIL_A: #REF!
Name CARRAIL_단면2차_X: #REF!
Name CARRAIL_단면2차_X: #REF!
Name CARRAIL_단면2차_X: #REF!
Name CARRAIL_단면2차_X: #REF!
Name CARRAIL_단면2차_Y: #REF!
Name CARRAIL_단면2차_Y: #REF!
Name CARRAIL_단면2차_Y: #REF!
Name CARRAIL_단면2차_Y: #REF!
Name CARRAIL_단면계수_X: #REF!
Name CARRAIL_단면계수_X: #REF!
Name CARRAIL_단면계수_X: #REF!
Name CARRAIL_단면계수_X: #REF!
Name CARRAIL_단면계수_Y: #REF!
Name CARRAIL_단면계수_Y: #REF!
Name CARRAIL_단면계수_Y: #REF!
Name CARRAIL_단면계수_Y: #REF!
Name CH: #REF!
Name CH: #REF!
Name CH: #REF!
Name CH: #REF!
Name COMPEN자중: #REF!
Name COMPEN자중: #REF!
Name COMPEN자중: #REF!
Name COMPEN자중: #REF!
Name CWT_BG: #REF!
Name CWT_BG: #REF!
Name CWT_BG: #REF!
Name CWT_BG: #REF!
Name CWT_RAIL: #REF!
Name CWT_RAIL: #REF!
Name CWT_RAIL: #REF!
Name CWT_RAIL: #REF!

Sheet SE 견적서
B3: 견 적 서(Special Edition)
B5: 주 소 : 서울시 종로구 율곡로 194 | J5: 견적일
B6: 대표이사 : 조 재 천 | J6: =DATE(MID(J9,7,4), MID(J9,11,2), MID(J9,13,2)) -> 46268
B7: 계약담당 : 김 승 훈
B8: 연 락 처 : H.P.) 010-8002-5506 | J8: 견적 No.
B9: E-Mail) sh.kim1@hdel.co.kr | J9: SE_인천_20260903-1
B11: 고객명(상호) 및 견적명 | G11: 현장명 및 현장주소
B13: 업 체 명 : | G13: 현 장 명 :
B14: 전화번호 : | G14: 현장주소 :
B15: ="견 적 명 : "&TRIM(REPLACE($G$13,1,8,""))&" 제어반 판매 견적서" -> 견 적 명 : 제어반 판매 견적서 | G15: 납품주소 : 협의장소
L16: 0.06 | M16: 0.05 | N16: 0.1 | O16: 0.11
B17: 1. 견적내역 | J17: (단위 : ￦) | O17: *영업이익 10% 이나, 합계금액 절사되는 것에 대한 보상으로 11% 적용
B19: 구분 | C19: NO. | D19: 품명 | E19: 호기 | F19: 규격 / 사양 | G19: 단위 | H19: 수량 | I19: 단가 | J19: 금액 | K19: 원가 | L19: 멀티플 | M19: 노무비 | N19: 간접비 | O19: 영업이익
B20: A. 패키지 | D20: SE-1 | F20: HC15-1SCO60-10 | G20: ST | H20: 1 | I20: =O20 -> 8786241.3 | J20: =H20*I20 -> 8786241.3 | K20: =IF('사양 입력'!$K$18="Y",'사양 입력'!$G$16+10000,'사양 입력'!$G$16) -> 6465353.8 | L20: =K20*(1+$L$16) -> 6853275 | M20: =L20*(1+$M$16) -> 7195938.8 | N20: =M20*(1+$N$16) -> 7915532.7 | O20: =N20*(1+$O$16) -> 8786241.3
D24: 구성품
D25: 제어반 ASSY | F25: ='사양 입력'!B18 -> MR, 일반형, 7.5KW, GI
D26: 의장 BOARD | F26: 사각 WHITE DOT 보드만 공급
D27: 승강로 부품일체 | F27: FLS,LCD, 승강로램프, 피트스위치
D28: CABLE ASSY | F28: HARNESS, T-CABLE 일체
D29: CAR TOP BOX | F29: INTERFACE BD or CONTROLLER
D30: 기타 잡자재 | F30: 플렉시블,덕트 외
F32: 소 계 | H32: =SUM(H20:H23) -> 1 | J32: =SUM(J20:J23) -> 8786241.3
G37: 합 계 | J37: =ROUNDDOWN(SUM(J32:J34),-4) -> 8780000
J38: (부가세 별도, 천단위 절사)
B39: [ 특 기 사 항 ]
B40: * 전기의장품은 보드만 공급됩니다.
B41: * 비상통화장치 관련자재 제외
B42: * 카도어 모터,엔코더 제외
B44: ※ OH,PIT,TRAVEL HEGHT 변경에 따라 가격변동이 발생 할 수 있음
B45: 1. 본 견적의 유효기간은 견적일로부터 30일 입니다.
B46: 2. 지불조건은 현금입니다.
B47: 3. 업무수행에 필요한 제반사항은 당사 승강기부품 제작공급 계약서에 따릅니다.
B50: 발주확인 및 승낙서
B51: 1) 상기 사항을 확인하였으며, 발주를 요청합니다. | G51: □ 발주자 확인
B52: 2) 발주확정금액 : 원정 (VAT별도) | G52: 발 주 일
B53: 3) 납기 요청일 : 년 월 일 | G53: 직 위
B54: 4) 대금지불은 청구일로부터 ( 30 )일 이내 현금지급 | G54: 발 주 일
B55: 5) 기타사항 : | G55: 성 명

Sheet 사양 입력
B1: 1. TM 및 건축 사양 | F1: 2. 제어반 사양 | J1: 3. 전장품 사양 및 옵션
B3: 건축 사양 | C3: DATA 입력 | F3: 제어 사양 | G3: 선택 | J3: 전장류 BD | K3: 수량(입력) | M3: MR | N3: =WBLX!AE6 -> 제어반 | O3: =WBLX!AF6 -> 2934692.1
A4: 입력 | B4: TM MODEL명 | E4: 선택 | F4: MR/MRL | G4: MR | I4: 선택 | J4: COP 사각형 DOT | K4: =IF(G9="YES",2,1) -> 1 | N4: =WBLX!AE7 -> 카탑 | O4: =WBLX!AF7 -> 358061
A5: 입력 | B5: 모터 용량 (KW) | C5: 6.3 | E5: 선택 | F5: 제어반 재질 | G5: GI | H5: =IF(AND($G$4="MR",$G$5="GI"),"",IF(AND($G$4="MR",$G$5="GI+PAINT"),"",IF(AND($G$4="MRL",$G$5="ALL SUS-HL"),"",IF(AND($G$4="MRL",$G$5="DOOR만 SUS-HL"),"",IF(AND($G$4="GD",$G$5="GI"),"",IF(AND($G$4="GD",$G$5="GI+PAINT"),"","◀재질")))))) | I5: 선택 | J5: HIP 사각형 DOT | K5: =C7-1 -> 14 | N5: =WBLX!AE8 -> 의장보드 | O5: =WBLX!AF8 -> 517867
A6: 입력 | B6: 모터 전류치 (A) | C6: 16 | E6: 선택 | F6: INVERTER 타입 | G6: 일반형 | J6: HPB | K6: =$C$7-($C$7-1) -> 1 | N6: =WBLX!AE9 -> 케이블 | O6: =WBLX!AF9 -> 1547807.8
A7: 입력 | B7: 건물 층수 | C7: 15 | E7: 선택 | F7: 출입구 높이(MRL 제어반) | G7: 2100 | I7: 선택 | J7: HPI 사각형 DOT | K7: =$C$7-($C$7-1) -> 1 | L7: =IF(표12[[#This Row],[전장류 BD]]="HPI 원형 DOT","BOX TYPE","") | N7: =WBLX!AE10 -> 승강로부품 | O7: =WBLX!AF10 -> 712835.6 | Q7: 창성 관리비용
A8: 입력 | B8: 엘리베이터 속도 | C8: 60 | E8: 선택 | F8: 장애인용 | G8: NO | I8: 선택 | J8: CPI 사각형 DOT | K8: 1 | N8: =WBLX!AE11 -> FLS | O8: =WBLX!AF11 -> 99740.295 | Q8: =SUM(O6:O8)*0.1 -> 236038.37
A9: 입력 | B9: 모터 정격 전압 | C9: 340 | E9: 선택 | F9: 관통형 | G9: NO | H9: =IF($G$9="YES","* 관통형일 경우, 견적 별도 문의바랍니다.","") | J9: 장애인 COP | K9: =IF(G8="YES",1,0) -> 0 | N9: 옵션 | O9: =WBLX!AF12 -> 0
E10: 선택 | F10: GROUP 운전 | G10: NO | J10: H.LANTERN | K10: 0
A11: 필요시 입력 | B11: OVER HEAD | C11: =IF($G$4="MRL",VLOOKUP($C$8,표18[],2,FALSE),VLOOKUP($C$8,표18_20[],2,FALSE)) -> 4350 | E11: 선택 | F11: MRL 도어 방향 | G11: RIGHT HINGE | I11: 선택 | J11: 비상통화장치 당사적용 | K11: N | M11: MRL | N11: =WBSS!AC6 -> 제어반 | O11: =WBSS!AD6 -> 1129369.1
A12: 필요시 입력 | B12: TRAVEL | C12: =C7*3000 -> 45000 | E12: 선택 | F12: TM ENCODER TYPE | G12: SINCOS | H12: =IF(AND($G$4="MR",$G$12="INCREMENTAL"),"",IF(AND($G$4="MR",$G$12="SINCOS"),"",IF(AND($G$4="MRL",$G$12="INCREMENTAL"),"",IF(AND($G$4="MRL",$G$12="SINCOS"),"",IF(AND($G$4="GD",$G$12="INCREMENTAL"),"",IF(AND($G$4="INCREMENTAL",$G$12="INCREMENTAL"),"","◀타입")))))) | I12: 선택 | J12: JOB SITE TOOL | K12: N | N12: =WBSS!AC7 -> 카탑 | O12: =WBSS!AD7 -> 358061
A13: 필요시 입력 | B13: PIT | C13: =IF($G$4="MRL",VLOOKUP($C$8,표18[],3,FALSE),VLOOKUP($C$8,표18_20[],3,FALSE)) -> 1250 | E13: 선택 | F13: 도어 인버터 전원 | G13: AC 220V | I13: 선택 | J13: T-CABLE 사양 | K13: 표준형 | N13: =WBSS!AC8 -> 의장보드 | O13: =WBSS!AD8 -> 517867
A14: 자동입력 | B14: TOTAL HEIGHT | C14: =C11+C12+C13 -> 50600 | E14: 선택 | F14: ROPE BRAKE | G14: EL TECH | J14: CCTV CABLE | K14: N | N14: =WBSS!AC9 -> 케이블 | O14: =WBSS!AD9 -> 1563575.2
J15: AIRCON CABLE | K15: N | N15: =WBSS!AC10 -> 승강로부품 | O15: =WBSS!AD10 -> 725061 | Q15: =SUM(O14:O16)*0.1 -> 238837.65
A16: 자동입력 | B16: INVETER 용량 | C16: =IF(AND(C5<=7.5,표20[모터 전류]<=18),"7.5KW",IF(AND(C5<=11,표20[모터 전류]<=25),"11KW",IF(AND(C5<=15,표20[모터 전류]<=34),"15KW",IF(AND(C5<=22,표20[모터 전류]<=51),"22KW",FALSE)))) -> 7.5KW | F16: 판매가(시행율 100%) | G16: =IF(G4="MRL",WBSS!AB6,IF(G4="MR",WBLX!AD6,WBST!AD6))+원가정보3!I722+VLOOKUP(J20,원가정보3!F723:I730,4,0) -> 6465353.8 | J16: 도어모터 + 엔코더 | K16: N | N16: =WBSS!AC11 -> FLS | O16: =WBSS!AD11 -> 99740.295
J17: 영진옵션(안전탑승,에스코드,범죄예방) | K17: N | N17: 옵션 | O17: =WBSS!AD12 -> 0
A18: 사양 | B18: =G4&", "&G6&", "&C16&", "&G5 -> MR, 일반형, 7.5KW, GI | J18: 성광옵션 | K18: N
J19: 4. 운송 지역 | M19: GD | N19: 제어반 | O19: =WBST!AF6 -> 633256.91
J20: 서울 | N20: 카탑 | O20: =WBST!AF7 -> 358061
N21: 의장보드 | O21: =WBST!AF8 -> 517867
N22: 케이블 | O22: =WBST!AF9 -> 1561949.4
N23: 승강로부품 | O23: =WBST!AF10 -> 657185.5
N24: FLS | O24: =WBST!AF11 -> 99740.295
N25: 옵션 | O25: =WBST!AF12 -> 0

Sheet WBLX
B2: WBLX
D3: 수배관련 203339L01현장 참고하여 작성
A5: NO | B5: 변경 | C5: Level | D5: 공사/파트 번호 | E5: seq | F5: 버전 | G5: 공사/파트 명 | H5: G/L CODE | I5: 오더 | J5: 품목구분 | K5: Block No | L5: 내/외작 | M5: 사급 | N5: 수정 | O5: 수량 | P5: 공사수량 | Q5: 주석 | R5: 공사주석 | S5: 전용 | T5: SPEC | U5: SIZE | V5: 특별조달유형 | W5: 단위 | X5: BOM등록자 | Y5: BOM등록일 | Z5: BOM수정일 | AA5: 별도자재 | AB5: 단가 | AC5: 금액 | AD5: 합계
C6: 1 | D6: =IF('사양 입력'!$G$4="MR",VLOOKUP('사양 입력'!$G$4&'사양 입력'!$G$5&'사양 입력'!$G$6&'사양 입력'!$C$16&'사양 입력'!$G$12,'CP ASSY'!$U$12:$V$251,2,FALSE),"ERROR") -> 20411101G0100 | G6: CP ASSY (내작) | H6: =LEFT(D6,11) -> 20411101G01 | O6: =IF(D6="ERROR","N/A",1) -> 1 | Q6: =VLOOKUP(D6,'CP ASSY'!$D$12:$L$251,9,0) -> 일반, 7.5KW, SINCOS, GI, , | X6: 조명석 | AB6: =VLOOKUP(D6,원가정보3!$E$5:$I$1048576,5,0) -> 167383.7 | AC6: =AB6*O6 -> 167383.7 | AD6: =SUMIF(AC6:AC110,"<>#n/a") -> 6171003.8 | AE6: 제어반 | AF6: =SUMIF(AC6:AC24,"<>#n/a") -> 2934692.1
D7: =VLOOKUP($D$6,'CP ASSY'!$V$12:$AA$251,6,FALSE)&"00" -> 20411102G0100 | G7: CP ASSY (외주) | H7: =LEFT(D7,11) -> 20411102G01 | O7: =IF('사양 입력'!G4="MR",1,"ERROR") -> 1 | X7: 조명석 | AB7: =VLOOKUP(D7,원가정보3!$E$5:$I$1048576,5,0) -> 1425100 | AC7: =AB7*O7 -> 1425100 | AE7: 카탑 | AF7: =AC62 -> 358061
D8: 20400790G0200 | G8: USAF BOARD | H8: 20400790G02 | O8: 1 | X8: 조명석 | AB8: =VLOOKUP(D8,원가정보3!$E$5:$I$1048576,5,0) -> 56393 | AC8: =AB8*O8 -> 56393 | AE8: 의장보드 | AF8: =SUM(AC71:AC84) -> 517867
D9: 20400900G0500 | G9: VCON BOARD | H9: 20400900G05 | O9: 1 | X9: 조명석 | AB9: =VLOOKUP(D9,원가정보3!$E$5:$I$1048576,5,0) -> 30754 | AC9: =AB9*O9 -> 30754 | AE9: 케이블 | AF9: =SUM(AC29:AC51) -> 1547807.8
D10: 20411025G0100 | G10: HHT-WB100N-SE ASSY | H10: 20411025G01 | O10: 1 | X10: 조명석 | AB10: =VLOOKUP(D10,원가정보3!$E$5:$I$1048576,5,0) -> 98455 | AC10: =AB10*O10 -> 98455 | AE10: 승강로부품 | AF10: =SUM(AC26:AC28)+SUM(AC52:AC61)+SUM(AC63:AC70) -> 712835.6
D11: 259D0202G0500 | G11: GROUP CABLE | L11: 외작(ROH) | O11: =IF('사양 입력'!$G$10="2 CAR",1,0) -> 0 | Q11: 15 MR | X11: 조명석 | AB11: =VLOOKUP(D11,원가정보3!$E$5:$I$1048576,5,0) -> 18270 | AC11: =AB11*O11 -> 0 | AE11: FLS | AF11: =AC25 -> 99740.295
C12: 2 | D12: =IF($S$12=20,"HX062002H0900",IF($S$12=30,"HX062002H1000",IF($S$12=40,"HX062002H1100",IF($S$12=50,"HX062002H1200",IF($S$12=60,"HX062002H1300",IF($S$12=75,"HX062002H1400",FALSE)))))) -> HX062002H1000 | G12: MCCB | H12: =LEFT(D12,11) -> HX062002H10 | O12: 1 | R12: 전류 | S12: ='DROP DOWN 지정'!$AG$11 -> 30 | X12: 조명석 | AB12: =VLOOKUP(D12,원가정보3!$E$5:$I$1048576,5,0) -> 34510 | AC12: =AB12*O12 -> 34510 | AE12: 옵션 | AF12: =SUM(AC99:AC104) -> 0
C13: 2 | D13: =IF('사양 입력'!$C$5<=11.3,"20410089G0600",IF(AND('사양 입력'!$C$5>11.3,'사양 입력'!$C$5<13),"20410089G0700",IF(AND('사양 입력'!$C$5>=13.1,'사양 입력'!$C$5<=14.1),"20410089G1000",IF(AND('사양 입력'!$C$5>=14.2,'사양 입력'!$C$5<=21),"20410089G0100",IF(AND('사양 입력'!$C$5>=21.1,'사양 입력'!$C$5<=26.5),"20410089G0800",IF(AND('사양 입력'!$C$5>=26.6,'사양 입력'!$C$5<=33),"20410089G0400","용량오류")))))) -> 20410089G0600 | G13: TERMINAL LUG | H13: =LEFT(D13,11) -> 20410089G06 | O13: 2 | X13: 조명석 | AB13: =VLOOKUP(D13,원가정보3!$E$5:$I$1048576,5,0) -> 7612 | AC13: =AB13*O13 -> 15224
C14: 2 | D14: =IF(AND('사양 입력'!$G$9="NO",'사양 입력'!$G$13="AC 220V"),"20401315G0200",IF(AND('사양 입력'!$G$9="NO",'사양 입력'!$G$13="AC 110V"),"20401315G1400",IF(AND('사양 입력'!$G$9="YES",'사양 입력'!$G$13="AC 220V"),"20401315G0300",IF(AND('사양 입력'!$G$9="YES",'사양 입력'!$G$13="AC 110V"),"20401315G1500",FALSE)))) -> 20401315G0200 | G14: TRANSFORMER | H14: =LEFT(D14,11) -> 20401315G02 | O14: 1 | X14: 조명석 | AB14: =VLOOKUP(D14,원가정보3!$E$5:$I$1048576,5,0) -> 90098 | AC14: =AB14*O14 -> 90098
C15: 2 | D15: HX001064H0400 | G15: CP NAME PLATE | H15: HX001064H04 | O15: 1 | X15: 조명석 | AB15: =VLOOKUP(D15,원가정보3!$E$5:$I$1048576,5,0) -> 339.416 | AC15: =AB15*O15 -> 339.416
C16: 2 | D16: 28500005G0100 | G16: LOAD SENSOR | H16: 28500005G01 | O16: 2 | X16: 조명석 | AB16: =VLOOKUP(D16,원가정보3!$E$5:$I$1048576,5,0) -> 13195 | AC16: =AB16*O16 -> 26390
D17: 20410326G0200 | G17: BYPASS BUZZER | H17: 20410326G02 | I17: BUY | J17: 1 | K17: 244A | L17: 외작(ROH) | N17: 1 | O17: 1 | T17: WBVF, LOCATION=CAR BOTTOM | U17: 220 | W17: EA | X17: 조명석 | Y17: 45002.589 | Z17: 45002.589 | AB17: =VLOOKUP(D17,원가정보3!$E$5:$I$1048576,5,0) -> 12768 | AC17: =AB17*O17 -> 12768
D18: 20401397G3000 | E18: 680 | F18: 0 | G18: HALL PWR OPT ASSY | H18: 20401397G30 | I18: BUY | J18: 1 | K18: 204B20 | L18: 외작(roh) | O18: =IF('DROP DOWN 지정'!$X$35>3000,1,0) -> 0 | T18: UNDER 12A, BELOW 30FL | U18: WITH BOX | W18: EA | X18: 조명석 | AB18: =VLOOKUP(D18,원가정보3!$E$5:$I$1048576,5,0) -> 79170 | AC18: =AB18*O18 -> 0
D19: 20400955G0200 | E19: 600 | F19: 0 | G19: FR OPT ASSY | H19: 20400955G02 | I19: BUY | J19: 1 | K19: 204B08 | L19: 외작(roh) | O19: =IF('사양 입력'!$C$14>31000,1,0) -> 1 | T19: FOR EMERGENCY (EN81-A3) | X19: 조명석 | AB19: =VLOOKUP(D19,원가정보3!$E$5:$I$1048576,5,0) -> 20300 | AC19: =AB19*O19 -> 20300
D20: 20600093G0100 | E20: 1390 | F20: 0 | G20: PC BOARD | H20: 20600093G01 | I20: BUY | J20: 1 | K20: 206A | L20: 외작(roh) | O20: =O19 -> 1 | T20: ELD RST SENSING BOARD | X20: 조명석 | AB20: =VLOOKUP(D20,원가정보3!$E$5:$I$1048576,5,0) -> 6830 | AC20: =AB20*O20 -> 6830
D21: 20411328G0100 | G21: CP MANUAL | O21: 1 | X21: 김승훈 | AB21: =VLOOKUP(D21,원가정보3!$E$5:$I$1048576,5,0) -> 12078 | AC21: =AB21*O21 -> 12078 | AD21: 추가 20231101
D22: =REPLACE($D$23,9,1,"P") -> 20302159P0200 | G22: INVERTER (내작) | O22: 1 | X22: 조명석 | AB22: =VLOOKUP(D22,원가정보3!$E$5:$I$1048576,5,0) -> 37552.9 | AC22: =AB22*O22 -> 37552.9
D23: =H23&"00" -> 20302159G0200 | G23: INVERTER (외주) | H23: =IF('사양 입력'!$G$4="MR",VLOOKUP('사양 입력'!$G$4&'사양 입력'!$G$5&'사양 입력'!$G$6&'사양 입력'!$C$16&'사양 입력'!$G$12,'CP ASSY'!$U$12:$Z$251,4,FALSE),"ERROR") -> 20302159G02 | O23: 1 | X23: 조명석 | AB23: =VLOOKUP(D23,원가정보3!$E$5:$I$1048576,5,0) -> 780280.6 | AC23: =AB23*O23 -> 780280.6
D24: =IF('사양 입력'!$G$4="MR",VLOOKUP('사양 입력'!$G$4&'사양 입력'!$G$5&'사양 입력'!$G$6&'사양 입력'!$C$16&'사양 입력'!$G$12,'CP ASSY'!$U$12:$Z$251,6,FALSE),"ERROR") -> HX045016H0300 | G24: PIM/IPM | H24: =LEFT(D24,11) -> HX045016H03 | O24: =IF('사양 입력'!$G$6="일반형",1,2) -> 1 | X24: 조명석 | AB24: =VLOOKUP(D24,원가정보3!$E$5:$I$1048576,5,0) -> 120235.5 | AC24: =AB24*O24 -> 120235.5
A25: 37 | C25: 1 | D25: =IF('사양 입력'!$C$8=30,"24110040G0100",IF('사양 입력'!$C$8=45,"24110040G0200",IF('사양 입력'!$C$8=60,"24110040G0300",IF('사양 입력'!$C$8=90,"24110040G0400",IF('사양 입력'!$C$8=105,"24110040G0500",IF('사양 입력'!$C$8=120,"24110040G0600",IF('사양 입력'!$C$8=150,"24110040G0700",FALSE))))))) -> 24110040G0300 | E25: 160 | F25: 0 | G25: FLS ASSY | H25: =LEFT(D25,11) -> 24110040G03 | I25: BUY | J25: 1 | K25: 241A | L25: 외작(ROH) | O25: 1 | Q25: * KS 케이블 적용 | T25: 13K RAIL, 105M/MIN | U25: . | W25: EA | X25: 조명석 | Y25: 45001.746 | AB25: =VLOOKUP(D25,원가정보3!$E$5:$I$1048576,5,0) -> 99740.295 | AC25: =AB25*O25 -> 99740.295
A26: 264 | C26: 1 | D26: 24200129G0200 | E26: 1570 | F26: 0 | G26: LCD ASSY | H26: 24200129G02 | I26: BUY | J26: 1 | K26: 242A | L26: 외작(ROH) | O26: 1 | T26: WBLX, WBSS1 (RAIL TYPE) | U26: 4MR | W26: EA | X26: 조명석 | Y26: 44964.611 | AB26: =VLOOKUP(D26,원가정보3!$E$5:$I$1048576,5,0) -> 43654.6 | AC26: =AB26*O26 -> 43654.6
A27: 265 | C27: 1 | D27: 24200128G0200 | E27: 1580 | F27: 0 | G27: LCD VANE ASSY | H27: 24200128G02 | I27: BUY | J27: 1 | K27: 242A01 | L27: 외작(ROH) | O27: ='사양 입력'!C7 -> 15 | Q27: 8~18K RAIL | T27: STOP | U27: 13K,18K RAIL | W27: EA | X27: 조명석 | Y27: 44964.611 | AB27: =VLOOKUP(D27,원가정보3!$E$5:$I$1048576,5,0) -> 3390.2 | AC27: =AB27*O27 -> 50853
A28: 266 | C28: 1 | D28: 242C0130G0100 | E28: 1590 | F28: 0 | G28: BRACKET | H28: 242C0130G01 | I28: BUY | J28: 1 | K28: 242A02 | L28: 외작(ROH) | O28: =ROUNDUP(O27/5,0) -> 3 | T28: L=500MM | U28: . | W28: EA | X28: 조명석 | Y28: 44964.611 | AB28: =VLOOKUP(D28,원가정보3!$E$5:$I$1048576,5,0) -> 806.3 | AC28: =AB28*O28 -> 2418.9
A29: 40 | C29: 1 | D29: =IF('사양 입력'!C7<10,"25900933G0"&'사양 입력'!C7&"00","25900933G"&'사양 입력'!C7&"00") -> 25900933G1500 | E29: 190 | F29: 0 | G29: CABLE | H29: =LEFT(D29,11) -> 25900933G15 | I29: BUY | J29: 3 | K29: 259A | L29: 외작(ROH) | O29: 1 | Q29: * CP TO DUCT HOLE (SA) : 5250(MM) * HALL COM & INT HARNESS용 TT 값 : 9850 * TOTAL HEIGHT (TH) : 38150(MM) * TRAVEL HEIGHT (TR) : 31150(MM) * OVER HEAD (OH) : 5200(MM) * PIT (PIT) : 1800(MM) * 비상용 엘리베이터 : NO * HA (통신) = 3500mm로 제작 * HB (INTERLOCK) = 200mm로 제작 * T-CABLE HARNESS는 25900972G01을 따를 것 | T29: FIELD HARNESS CABLE (EN81-20/50) | U29: 11 | W29: EA | X29: 조명석 | Y29: 45001.746 | AB29: =VLOOKUP(D29,원가정보3!$E$5:$I$1048576,5,0) -> 131715.1 | AC29: =AB29*O29 -> 131715.1
A30: 41 | C30: 1 | D30: 25900888G0100 | E30: 200 | F30: 0 | G30: CABLE | H30: 25900888G01 | I30: BUY | J30: 3 | K30: 259A22 | L30: 외작(ROH) | O30: 1 | T30: FOR EN-20/50 | U30: . | W30: EA | X30: 조명석 | Y30: 45001.746 | AB30: =VLOOKUP(D30,원가정보3!$E$5:$I$1048576,5,0) -> 13311.1 | AC30: =AB30*O30 -> 13311.1
A31: 42 | C31: 1 | D31: 25900980G0900 | E31: 210 | F31: 0 | G31: CABLE ASSY | H31: 25900980G09 | I31: BUY | J31: 3 | K31: 259A22 | L31: 외작(ROH) | O31: 1 | T31: FOR PIT LAMP | U31: . | W31: EA | X31: 조명석 | Y31: 45001.746 | AB31: =VLOOKUP(D31,원가정보3!$E$5:$I$1048576,5,0) -> 3059.1 | AC31: =AB31*O31 -> 3059.1
D32: 25900932G2000 | E32: 1600 | F32: 1 | G32: CABLE | H32: 25900932G20 | I32: BUY | J32: 3 | K32: 259A40 | L32: 외작(roh) | O32: =IF(O27<=20,O18,0) -> 0 | T32: OVER 3A, 1CORE | X32: 조명석 | AB32: =VLOOKUP(D32,원가정보3!$E$5:$I$1048576,5,0) -> 22330 | AC32: =AB32*O32 -> 0
D33: 25900932G3000 | E33: 1600 | F33: 1 | G33: CABLE | H33: 25900932G30 | I33: BUY | J33: 3 | K33: 259A40 | L33: 외작(roh) | O33: =IF(AND(O27>20,O27<30),O18,0) -> 0 | T33: OVER 3A, 1CORE | X33: 조명석 | AB33: =VLOOKUP(D33,원가정보3!$E$5:$I$1048576,5,0) -> 32378.5 | AC33: =AB33*O33 -> 0
A34: 43 | C34: 1 | D34: =IF('사양 입력'!$C$5<=7,"HX058004H0200",IF(AND('사양 입력'!$C$5>=7.1,'사양 입력'!$C$5<=11.3),"HX058004H0300",IF(AND('사양 입력'!$C$5>=11.4,'사양 입력'!$C$5<=14.1),"HX058004H0400",IF(AND('사양 입력'!$C$5>=14.2,'사양 입력'!$C$5<=20.6),"HX058004H0500",IF(AND('사양 입력'!$C$5>=20.7,'사양 입력'!$C$5<=26.5),"HX058004H0600",IF(AND('사양 입력'!$C$5>=26.6,'사양 입력'!$C$5<=33),"HX058004H0700",IF(AND('사양 입력'!$C$5>=33.1,'사양 입력'!$C$5<=50),"HX058004H0800","용량오류"))))))) -> HX058004H0200 | E34: 220 | F34: 0 | G34: POWER CABLE | H34: =LEFT(D34,11) -> HX058004H02 | I34: BUY | J34: 3 | K34: 259B01 | L34: 외작(ROH) | O34: 54 | Q34: POWER TO CP - 3 CORE 27 CP TO MOTOR - 3 CORE 27 | T34: KIV 16.0MMSQx1C, BLACK | U34: 750V, 70℃ | W34: M | X34: 조명석 | Y34: 45001.746 | AB34: =VLOOKUP(D34,원가정보3!$E$5:$I$1048576,5,0) -> 1027.4 | AC34: =AB34*O34 -> 55479.6
A35: 44 | C35: 1 | D35: =IF('사양 입력'!$C$5<=7,"HX058006H0200",IF(AND('사양 입력'!$C$5>=7.1,'사양 입력'!$C$5<=11.3),"HX058006H0300",IF(AND('사양 입력'!$C$5>=11.4,'사양 입력'!$C$5<=14.1),"HX058006H0400",IF(AND('사양 입력'!$C$5>=14.2,'사양 입력'!$C$5<=33),"HX058006H0500",IF(AND('사양 입력'!$C$5>=33.1,'사양 입력'!$C$5<=50),"HX058006H0600","용량오류"))))) -> HX058006H0200 | E35: 230 | F35: 1 | G35: CABLE | H35: =LEFT(D35,11) -> HX058006H02 | I35: BUY | J35: 3 | K35: 259B02 | L35: 외작(ROH) | O35: 18 | Q35: POWER TO CP - 1 CORE 9 CP TO MOTOR - 1 CORE 9 | T35: KIV 16SQ(GREEN-YELLOW) | U35: 750V, 70℃ | W35: M | X35: 조명석 | Y35: 45001.746 | AB35: =VLOOKUP(D35,원가정보3!$E$5:$I$1048576,5,0) -> 1027.4 | AC35: =AB35*O35 -> 18493.2
A36: 45 | C36: 1 | D36: HX058004H0100 | E36: 240 | F36: 0 | G36: LIGHTING CABLE | H36: HX058004H01 | I36: BUY | J36: 3 | K36: 259B03 | L36: 외작(ROH) | O36: 20 | Q36: POWER TO CP - 2 CORE 20 | T36: KIV 2.5MMSQx1C, BLACK | U36: 750V, 70℃ | W36: M | X36: 조명석 | Y36: 45001.746 | AB36: =VLOOKUP(D36,원가정보3!$E$5:$I$1048576,5,0) -> 671 | AC36: =AB36*O36 -> 13420
A37: 46 | C37: 1 | D37: HX058017H0100 | E37: 250 | F37: 0 | G37: CABLE | H37: HX058017H01 | I37: BUY | J37: 3 | K37: 259B04 | L37: 외작(ROH) | O37: 10 | Q37: FOR T-CABLE BINDING | T37: IV 2.0SQ,BLUE | U37: . | W37: M | X37: 조명석 | Y37: 45001.746 | AB37: =VLOOKUP(D37,원가정보3!$E$5:$I$1048576,5,0) -> 378.4 | AC37: =AB37*O37 -> 3784
A38: 47 | C38: 1 | D38: HX058010H0900 | E38: 260 | F38: 0 | G38: CABLE | H38: HX058010H09 | I38: BUY | J38: 3 | K38: 259B09 | L38: 외작(ROH) | O38: 11 | Q38: WAY TO PIT - 1 CORE 3 CP TO MOTOR THERMAL SW - 1 CORE 8 | T38: EVV 0.75SQ x 3C | U38: KS IEC 60227 | W38: M | X38: 조명석 | Y38: 45001.746 | AB38: =VLOOKUP(D38,원가정보3!$E$5:$I$1048576,5,0) -> 817.3 | AC38: =AB38*O38 -> 8990.3
A39: 48 | C39: 1 | D39: HX058010H1000 | E39: 270 | F39: 0 | G39: CABLE | H39: HX058010H10 | I39: BUY | J39: 3 | K39: 259B10 | L39: 외작(ROH) | O39: 4 | Q39: WAY TO PIT LAMP - 1 CORE 4 | T39: EVV 0.75SQ x 5C | U39: KS IEC 60227(EN 50525) | W39: M | X39: 조명석 | Y39: 45001.746 | AB39: =VLOOKUP(D39,원가정보3!$E$5:$I$1048576,5,0) -> 1196.8 | AC39: =AB39*O39 -> 4787.2
A40: 49 | C40: 1 | D40: HX058010H1200 | E40: 280 | F40: 0 | G40: CABLE | H40: HX058010H12 | I40: BUY | J40: 3 | K40: 259B11 | L40: 외작(ROH) | O40: =ROUNDUP(8+14+4+8.2+('사양 입력'!C12+'사양 입력'!C11)/1000,0) -> 84 | Q40: CP TO TM BRAKE - 1 CORE 8 CP TO PIT(HIP & HPI & INTERLOCK) - 1 CORE 45 CP TO FLS(UPPER) - 1 CORE 14 WAY TO FLS(LOWER) - 1 CORE 4 | T40: EVV 0.75SQ x 8C | U40: KS IEC 60227 | W40: M | X40: 조명석 | Y40: 45001.746 | AB40: =VLOOKUP(D40,원가정보3!$E$5:$I$1048576,5,0) -> 1767.7 | AC40: =AB40*O40 -> 148486.8
A41: 50 | C41: 1 | D41: HX058010H1500 | E41: 290 | F41: 0 | G41: CABLE | H41: HX058010H15 | I41: BUY | J41: 3 | K41: 259B13 | L41: 외작(ROH) | O41: =ROUNDUP(11+('사양 입력'!$C$11+'사양 입력'!$C$12)/1000,0) -> 61 | Q41: CP TO PIT ASSY - 1 CORE 48 | T41: EVV 0.75SQ x 20C | U41: KS IEC 60227 | W41: M | X41: 조명석 | Y41: 45001.746 | AB41: =VLOOKUP(D41,원가정보3!$E$5:$I$1048576,5,0) -> 3997.4 | AC41: =AB41*O41 -> 243841.4
D42: HX058014H0200 | E42: 1680 | F42: 0 | G42: CABLE | H42: HX058014H02 | I42: BUY | J42: 3 | K42: 259B18 | L42: 외작(roh) | O42: =IF(O18>=1,ROUNDUP((5000+'사양 입력'!$C$11+'사양 입력'!$C$12+4000)/1000,0),0) -> 0 | Q42: CP TO HALL POWER 1 - 1 CORE 99 | T42: EVV 1.5SQ x 4C | X42: 조명석 | AB42: =VLOOKUP(D42,원가정보3!$E$5:$I$1048576,5,0) -> 1745.7 | AC42: =AB42*O42 -> 0
...

Sheet WBSS
B2: WBSS
D3: 수배관련 202619L02현장 참고하여 작성
A5: NO | B5: 변경 | C5: Level | D5: 공사/파트 번호 | E5: seq | F5: 버전 | G5: 공사/파트 명 | H5: G/L CODE | I5: 오더 | J5: 품목구분 | K5: Block No | L5: 내/외작 | M5: 사급 | N5: 수정 | O5: 수량 | P5: 공사수량 | Q5: 주석 | R5: 공사주석 | S5: 전용 | T5: SPEC | U5: SIZE | V5: 특별조달유형 | W5: 단위 | X5: BOM등록자 | Y5: 별도자재 | Z5: 단가 | AA5: 금액 | AB5: 합계
C6: 1 | D6: =IF('사양 입력'!$G$4="MRL",VLOOKUP('사양 입력'!$G$4&'사양 입력'!$G$5&'사양 입력'!$G$6&'사양 입력'!$G$7&'사양 입력'!$C$16&'사양 입력'!$G$12&'사양 입력'!$G$11,'CP ASSY'!$U$12:$V$251,2,FALSE),"ERROR") -> ERROR | G6: CP ASSY (내작) | H6: =LEFT(D6,11) -> ERROR | O6: =IF(D6="ERROR","N/A",1) -> N/A | Q6: =VLOOKUP($D$6,'CP ASSY'!$V$12:$W$251,2,FALSE) -> #N/A | X6: 조명석 | Z6: =VLOOKUP(D6,원가정보3!$E$5:$K$1048576,5,0) -> #N/A | AA6: =Z6*O6 -> #N/A | AB6: =SUMIF(AA6:AA137,"<>#n/a") -> 4393673.6 | AC6: 제어반 | AD6: =SUMIF(AA6:AA30,"<>#n/a") -> 1129369.1
D7: =VLOOKUP($D$6,'CP ASSY'!$V$12:$AA$251,6,FALSE)&"00" -> #N/A | G7: CP ASSY (외주) | H7: =LEFT(D7,11) -> #N/A | O7: =IF('사양 입력'!G4="MRL",1,"ERROR") -> ERROR | X7: 조명석 | Z7: =VLOOKUP(D7,원가정보3!$E$5:$K$1048576,5,0) -> #N/A | AA7: =Z7*O7 -> #N/A | AC7: 카탑 | AD7: =AA67 -> 358061
D8: =H8&"00" -> #N/A | G8: CABINET ASSY | H8: =VLOOKUP($D$6,'CP ASSY'!$D$12:$E$251,2,0) -> #N/A | O8: 1 | Q8: =VLOOKUP(D6,'CP ASSY'!$D$12:$L$251,9,0) -> #N/A | X8: 조명석 | Z8: =VLOOKUP(D8,원가정보3!$E$5:$K$1048576,5,0) -> #N/A | AA8: =Z8*O8 -> #N/A | AC8: 의장보드 | AD8: =SUM(AA76:AA89) -> 517867
D9: 20400790G0200 | G9: USAF BOARD | H9: 20400790G02 | O9: 1 | Q9: USAF BOARD | R9: WBLX-SE,WBSS-SE | X9: 조명석 | Z9: =VLOOKUP(D9,원가정보3!$E$5:$K$1048576,5,0) -> 56393 | AA9: =Z9*O9 -> 56393 | AC9: 케이블 | AD9: =SUM(AA35:AA56) -> 1563575.2
D10: 20400900G0500 | G10: VCON BOARD | H10: 20400900G05 | O10: 1 | Q10: VCON BOARD | R10: WBLX-SE, WBSS-SE | X10: 조명석 | Z10: =VLOOKUP(D10,원가정보3!$E$5:$K$1048576,5,0) -> 30754 | AA10: =Z10*O10 -> 30754 | AC10: 승강로부품 | AD10: =SUM(AA32:AA34)+SUM(AA57:AA66)+SUM(AA68:AA75) -> 725061
D11: 20411025G0100 | G11: HHT | H11: 20411025G01 | O11: 1 | Q11: HHT | X11: 조명석 | Z11: =VLOOKUP(D11,원가정보3!$E$5:$K$1048576,5,0) -> 98455 | AA11: =Z11*O11 -> 98455 | AC11: FLS | AD11: =AA31 -> 99740.295
D12: 259D0202G0500 | G12: GROUP CABLE | L12: 외작(ROH) | O12: =IF('사양 입력'!$G$10="2 CAR",1,0) -> 0 | Q12: 15 MR | X12: 조명석 | Z12: =VLOOKUP(D12,원가정보3!$E$5:$K$1048576,5,0) -> 18270 | AA12: =Z12*O12 -> 0 | AC12: 옵션 | AD12: =SUM(AA99:AA104) -> 0
C13: 2 | D13: ="HX062002H"&'DROP DOWN 지정'!AG11&"00" -> HX062002H3000 | G13: MCCB | H13: =LEFT(D13,11) -> HX062002H30 | O13: 1 | X13: 조명석 | Z13: =VLOOKUP(D13,원가정보3!$E$5:$K$1048576,5,0) -> 20807 | AA13: =Z13*O13 -> 20807
C14: 2 | D14: =IF('사양 입력'!$C$5<=11.3,"20410089G0600",IF(AND('사양 입력'!$C$5>11.3,'사양 입력'!$C$5<13),"20410089G0700",IF(AND('사양 입력'!$C$5>=13.1,'사양 입력'!$C$5<=14.1),"20410089G1000",IF(AND('사양 입력'!$C$5>=14.2,'사양 입력'!$C$5<=21),"20410089G0100",IF(AND('사양 입력'!$C$5>=21.1,'사양 입력'!$C$5<=26.5),"20410089G0800",IF(AND('사양 입력'!$C$5>=26.6,'사양 입력'!$C$5<=33),"20410089G0400","용량오류")))))) -> 20410089G0600 | G14: TERMINAL LUG | H14: =LEFT(D14,11) -> 20410089G06 | O14: 2 | X14: 조명석 | Z14: =VLOOKUP(D14,원가정보3!$E$5:$K$1048576,5,0) -> 7612 | AA14: =Z14*O14 -> 15224
C15: 2 | D15: =IF(AND('사양 입력'!$G$9="NO",'사양 입력'!$G$13="AC 220V"),"20401315G0200",IF(AND('사양 입력'!$G$9="NO",'사양 입력'!$G$13="AC 110V"),"20401315G1400",IF(AND('사양 입력'!$G$9="YES",'사양 입력'!$G$13="AC 220V"),"20401315G0300",IF(AND('사양 입력'!$G$9="YES",'사양 입력'!$G$13="AC 110V"),"20401315G1500",FALSE)))) -> 20401315G0200 | G15: TRANSFORMER | H15: =LEFT(D15,11) -> 20401315G02 | O15: 1 | X15: 조명석 | Z15: =VLOOKUP(D15,원가정보3!$E$5:$K$1048576,5,0) -> 90098 | AA15: =Z15*O15 -> 90098
C16: 2 | D16: 20410485G0500 | G16: ELD OPT ASSY (현대 ELD) | H16: 20410485G05 | O16: 1 | X16: 조명석 | Z16: =VLOOKUP(D16,원가정보3!$E$5:$K$1048576,5,0) -> 17255 | AA16: =Z16*O16 -> 17255
C17: 2 | D17: HX001064H0400 | G17: CP NAME PLATE | H17: HX001064H04 | O17: 1 | X17: 조명석 | Z17: =VLOOKUP(D17,원가정보3!$E$5:$K$1048576,5,0) -> 339.416 | AA17: =Z17*O17 -> 339.416
C18: 2 | D18: 28500005G0100 | G18: LOAD SENSOR | H18: 28500005G01 | L18: 외작(ROH) | O18: 2 | X18: 조명석 | Z18: =VLOOKUP(D18,원가정보3!$E$5:$K$1048576,5,0) -> 13195 | AA18: =Z18*O18 -> 26390
A19: 42 | C19: 1 | D19: 20410326G0200 | E19: 490 | F19: 0 | G19: BYPASS BUZZER | H19: 20410326G02 | I19: BUY | J19: 1 | K19: 244A | L19: 외작(ROH) | N19: 1 | O19: 1 | T19: WBVF, LOCATION=CAR BOTTOM | U19: 220 | W19: EA | X19: 조명석 | Z19: =VLOOKUP(D19,원가정보3!$E$5:$K$1048576,5,0) -> 12768 | AA19: =Z19*O19 -> 12768
D20: 20401194G3000 | E20: 680 | F20: 0 | G20: HALL PWR OPT ASSY | H20: 20401194G30 | I20: BUY | J20: 1 | K20: 204B20 | L20: 외작(roh) | O20: =IF('DROP DOWN 지정'!$X$35>3000,1,0) -> 0 | T20: UNDER 12A, BELOW 30FL | U20: WITH BOX | W20: EA | X20: 조명석 | Z20: =VLOOKUP(D20,원가정보3!$E$5:$K$1048576,5,0) -> 142100 | AA20: =Z20*O20 -> 0
D21: 20400955G0200 | E21: 600 | F21: 0 | G21: FR OPT ASSY | H21: 20400955G02 | I21: BUY | J21: 1 | K21: 204B08 | L21: 외작(roh) | O21: =IF('사양 입력'!$C$14>31000,1,0) -> 1 | T21: FOR EMERGENCY (EN81-A3) | X21: 조명석 | Z21: =VLOOKUP(D21,원가정보3!$E$5:$K$1048576,5,0) -> 20300 | AA21: =Z21*O21 -> 20300
C22: 1 | D22: =IF($T$22<=15,"20610102G0900",IF(AND($T$22>=22,$T$22<=30),"20610102G1100","용량오류")) -> 20610102G0900 | G22: ELD | H22: =LEFT(D22,11) -> 20610102G09 | O22: 1 | R22: 인버터 용량 | S22: =SUBSTITUTE('사양 입력'!C16,"KW","") -> 7.5 | T22: =S22*1 -> 7.5 | X22: 조명석 | Z22: =VLOOKUP(D22,원가정보3!$E$5:$K$1048576,5,0) -> 617123.1 | AA22: =Z22*O22 -> 617123.1
D23: 20600093G0100 | E23: 1390 | F23: 0 | G23: PC BOARD | H23: 20600093G01 | I23: BUY | J23: 1 | K23: 206A | L23: 외작(roh) | O23: =O21 -> 1 | T23: ELD RST SENSING BOARD | X23: 조명석 | Z23: =VLOOKUP(D23,원가정보3!$E$5:$K$1048576,5,0) -> 6830 | AA23: =Z23*O23 -> 6830
D24: =REPLACE($D$25,9,1,"P") -> ERROR00P | G24: INVERTER (내작) | O24: 1 | X24: 조명석 | Z24: =VLOOKUP(D24,원가정보3!$E$5:$K$1048576,5,0) -> #N/A | AA24: =Z24*O24 -> #N/A
D25: =H25&"00" -> ERROR00 | G25: INVERTER (외주) | H25: =IF('사양 입력'!$G$4="MRL",VLOOKUP('사양 입력'!$G$4&'사양 입력'!$G$5&'사양 입력'!$G$6&'사양 입력'!$G$7&'사양 입력'!$C$16&'사양 입력'!$G$12&'사양 입력'!$G$11,'CP ASSY'!$U$12:$Z$251,4,FALSE),"ERROR") -> ERROR | O25: 1 | X25: 조명석 | Z25: =VLOOKUP(D25,원가정보3!$E$5:$K$1048576,5,0) -> #N/A | AA25: =Z25*O25 -> #N/A
D26: =IF('사양 입력'!$G$4="MRL",VLOOKUP('사양 입력'!$G$4&'사양 입력'!$G$5&'사양 입력'!$G$6&'사양 입력'!$G$7&'사양 입력'!$C$16&'사양 입력'!$G$12&'사양 입력'!$G$11,'CP ASSY'!$U$12:$Z$251,6,FALSE),"ERROR") -> ERROR | G26: PIM/IPM | H26: =LEFT(D26,11) -> ERROR | O26: =IF('사양 입력'!$G$6="일반형",1,2) -> 1 | X26: 조명석 | Z26: =VLOOKUP(D26,원가정보3!$E$5:$K$1048576,5,0) -> #N/A | AA26: =Z26*O26 -> #N/A
D27: 20411328G0100 | G27: CP MANUAL | H27: 20411328G01 | O27: 1 | X27: 김승훈 | Z27: =VLOOKUP(D27,원가정보3!$E$5:$K$1048576,5,0) -> 12078 | AA27: =Z27*O27 -> 12078 | AB27: 추가 20231101
C28: 1 | D28: =IF($T$22<=7.5,"20610066G0100",IF($T$22=11,"20610066G0200",IF($T$22=15,"20610066G0300",IF($T$22=22,"20610066G0400","용량오류")))) -> 20610066G0100 | G28: ELD CABLE ASSY | H28: =LEFT(D28,11) -> 20610066G01 | O28: 5 | X28: 조명석 | Z28: =VLOOKUP(D28,원가정보3!$E$5:$K$1048576,5,0) -> 5075 | AA28: =Z28*O28 -> 25375
C29: 1 | D29: =IF($T$22<=7.5,"20610072G0100",IF($T$22=11,"20610072G0300",IF($T$22=15,"20610072G0500",IF($T$22=22,"20610072G0700","용량오류")))) -> 20610072G0100 | G29: ELD HARNESS CABLE ASSY | H29: =LEFT(D29,11) -> 20610072G01 | O29: 1 | X29: 조명석 | Z29: =VLOOKUP(D29,원가정보3!$E$5:$K$1048576,5,0) -> 10159.6 | AA29: =Z29*O29 -> 10159.6
C30: 1 | D30: =IF('사양 입력'!$C$16="7.5KW","20401225G0300",IF('사양 입력'!$C$16="11KW","20401225G0900",IF('사양 입력'!$C$16="15KW","20401225G1900",IF('사양 입력'!$C$16="22KW","20410388G0300","용량오류")))) -> 20401225G0300 | G30: RESISTOR BOX | H30: =LEFT(D30,11) -> 20401225G03 | O30: 1 | X30: 조명석 | Z30: =VLOOKUP(D30,원가정보3!$E$5:$K$1048576,5,0) -> 69020 | AA30: =Z30*O30 -> 69020
A31: 263 | C31: 1 | D31: =IF('사양 입력'!$C$8=30,"24110040G1100",IF('사양 입력'!$C$8=45,"24110040G1200",IF('사양 입력'!$C$8=60,"24110040G1300",IF('사양 입력'!$C$8=90,"24110040G1400",IF('사양 입력'!$C$8=105,"24110040G1500",IF('사양 입력'!$C$8=120,"24110040G1600",IF('사양 입력'!$C$8=150,"24110040G1700",FALSE))))))) -> 24110040G1300 | E31: 1560 | F31: 1 | G31: FLS ASSY | H31: =LEFT(D31,11) -> 24110040G13 | I31: BUY | J31: 1 | K31: 241A | L31: 외작(ROH) | O31: 1 | Q31: * IP x3 LIMIT SW 적용 * KS 케이블 적용 | T31: 18K RAIL, 90M/MIN | U31: . | W31: EA | X31: 조명석 | Z31: =VLOOKUP(D31,원가정보3!$E$5:$K$1048576,5,0) -> 99740.295 | AA31: =Z31*O31 -> 99740.295
A32: 264 | C32: 1 | D32: 24200129G0200 | E32: 1570 | F32: 0 | G32: LCD ASSY | H32: 24200129G02 | I32: BUY | J32: 1 | K32: 242A | L32: 외작(ROH) | O32: 1 | T32: WBLX, WBSS1 (RAIL TYPE) | U32: 4MR | W32: EA | X32: 조명석 | Z32: =VLOOKUP(D32,원가정보3!$E$5:$K$1048576,5,0) -> 43654.6 | AA32: =Z32*O32 -> 43654.6
A33: 265 | C33: 1 | D33: 24200128G0200 | E33: 1580 | F33: 0 | G33: LCD VANE ASSY | H33: 24200128G02 | I33: BUY | J33: 1 | K33: 242A01 | L33: 외작(ROH) | O33: ='사양 입력'!C7 -> 15 | Q33: 8~18K RAIL | T33: STOP | U33: 13K,18K RAIL | W33: EA | X33: 조명석 | Z33: =VLOOKUP(D33,원가정보3!$E$5:$K$1048576,5,0) -> 3390.2 | AA33: =Z33*O33 -> 50853
A34: 266 | C34: 1 | D34: 242C0130G0100 | E34: 1590 | F34: 0 | G34: BRACKET | H34: 242C0130G01 | I34: BUY | J34: 1 | K34: 242A02 | L34: 외작(ROH) | O34: =ROUNDUP(O33/5,0) -> 3 | T34: L=500MM | U34: . | W34: EA | X34: 조명석 | Z34: =VLOOKUP(D34,원가정보3!$E$5:$K$1048576,5,0) -> 806.3 | AA34: =Z34*O34 -> 2418.9
A35: 267 | C35: 1 | D35: =IF('사양 입력'!$C$7<10,"25900914G0"&'사양 입력'!$C$7&"00","25900914G"&'사양 입력'!$C$7&"00") -> 25900914G1500 | E35: 1600 | F35: 0 | G35: CABLE | H35: =LEFT(D35,11) -> 25900914G15 | I35: BUY | J35: 3 | K35: 259A | L35: 외작(ROH) | O35: 1 | Q35: * CP TO DUCT HOLE (SA) : 5000(MM) * 기계실 돌림 배관 (SF) : 2000(MM) * HALL COM & INT HARNESS용 TT 값 : 10460(MM) * TOTAL HEIGHT (TH) : 64000(MM) * TRAVEL HEIGHT (TR) : 57600(MM) * OVER HEAD (OH) : 5000(MM) * PIT (PIT) : 1400(MM) * 비상용 엘리베이터 : YES * HA (통신) = 3500mm로 제작 * HB (INTERLOCK) = 400mm로 제작 * T-CABLE HARNESS는 25900972G01을 따를 것 * WBSS2 승강로 취부형 제어반 적용 | T35: FIELD HARNESS CABLE(EN81-20/50) | U35: 15 | W35: EA | X35: 조명석 | Z35: =VLOOKUP(D35,원가정보3!$E$5:$K$1048576,5,0) -> 201983.1 | AA35: =Z35*O35 -> 201983.1
A36: 268 | C36: 1 | D36: 25900888G0100 | E36: 1610 | F36: 0 | G36: CABLE | H36: 25900888G01 | I36: BUY | J36: 3 | K36: 259A22 | L36: 외작(ROH) | O36: 1 | T36: FOR EN-20/50 | U36: . | W36: EA | X36: 조명석 | Z36: =VLOOKUP(D36,원가정보3!$E$5:$K$1048576,5,0) -> 13311.1 | AA36: =Z36*O36 -> 13311.1
A37: 269 | C37: 1 | D37: 25900980G0900 | E37: 1620 | F37: 0 | G37: CABLE ASSY | H37: 25900980G09 | I37: BUY | J37: 3 | K37: 259A22 | L37: 외작(ROH) | O37: 1 | T37: FOR PIT LAMP | U37: . | W37: EA | X37: 조명석 | Z37: =VLOOKUP(D37,원가정보3!$E$5:$K$1048576,5,0) -> 3059.1 | AA37: =Z37*O37 -> 3059.1
D38: 25900932G2000 | E38: 1600 | F38: 1 | G38: CABLE | H38: 25900932G20 | I38: BUY | J38: 3 | K38: 259A40 | L38: 외작(roh) | O38: =IF(O33<=20,O20,0) -> 0 | T38: OVER 3A, 1CORE | X38: 조명석 | Z38: =VLOOKUP(D38,원가정보3!$E$5:$K$1048576,5,0) -> 22330 | AA38: =Z38*O38 -> 0
D39: 25900932G3000 | E39: 1600 | F39: 1 | G39: CABLE | H39: 25900932G30 | I39: BUY | J39: 3 | K39: 259A40 | L39: 외작(roh) | O39: =IF(AND(O33>20,O33<30),O20,0) -> 0 | T39: OVER 3A, 1CORE | X39: 조명석 | Z39: =VLOOKUP(D39,원가정보3!$E$5:$K$1048576,5,0) -> 32378.5 | AA39: =Z39*O39 -> 0
A40: 270 | C40: 1 | D40: =IF('사양 입력'!$C$5<=7,"HX058004H0200",IF(AND('사양 입력'!$C$5>=7.1,'사양 입력'!$C$5<=11.3),"HX058004H0300",IF(AND('사양 입력'!$C$5>=11.4,'사양 입력'!$C$5<=14.1),"HX058004H0400",IF(AND('사양 입력'!$C$5>=14.2,'사양 입력'!$C$5<=20.6),"HX058004H0500",IF(AND('사양 입력'!$C$5>=20.7,'사양 입력'!$C$5<=26.5),"HX058004H0600",IF(AND('사양 입력'!$C$5>=26.6,'사양 입력'!$C$5<=33),"HX058004H0700",IF(AND('사양 입력'!$C$5>=33.1,'사양 입력'!$C$5<=50),"HX058004H0800","용량오류"))))))) -> HX058004H0200 | E40: 1630 | F40: 0 | G40: POWER CABLE | H40: =LEFT(D40,11) -> HX058004H02 | I40: BUY | J40: 3 | K40: 259B01 | L40: 외작(ROH) | O40: 48 | Q40: CP TO MOTOR - 3 CORE 48 | T40: KIV 16.0MMSQx1C, BLACK | U40: 750V, 70℃ | W40: M | X40: 조명석 | Z40: =VLOOKUP(D40,원가정보3!$E$5:$K$1048576,5,0) -> 1027.4 | AA40: =Z40*O40 -> 49315.2
A41: 271 | C41: 1 | D41: =IF('사양 입력'!$C$5<=7,"HX058006H0200",IF(AND('사양 입력'!$C$5>=7.1,'사양 입력'!$C$5<=11.3),"HX058006H0300",IF(AND('사양 입력'!$C$5>=11.4,'사양 입력'!$C$5<=14.1),"HX058006H0400",IF(AND('사양 입력'!$C$5>=14.2,'사양 입력'!$C$5<=33),"HX058006H0500",IF(AND('사양 입력'!$C$5>=33.1,'사양 입력'!$C$5<=50),"HX058006H0600","용량오류"))))) -> HX058006H0200 | E41: 1640 | F41: 1 | G41: CABLE | H41: HX058006H05 | I41: BUY | J41: 3 | K41: 259B02 | L41: 외작(ROH) | O41: 16 | Q41: CP TO MOTOR - 1 CORE 16 | T41: KIV 16SQ(GREEN-YELLOW) | U41: 750V, 70℃ | W41: M | X41: 조명석 | Z41: =VLOOKUP(D41,원가정보3!$E$5:$K$1048576,5,0) -> 1027.4 | AA41: =Z41*O41 -> 16438.4
A42: 272 | C42: 1 | D42: HX058017H0100 | E42: 1650 | F42: 0 | G42: CABLE | H42: HX058017H01 | I42: BUY | J42: 3 | K42: 259B04 | L42: 외작(ROH) | O42: 10 | Q42: FOR T-CABLE BINDING | T42: IV 2.0SQ,BLUE | U42: . | W42: M | X42: 조명석 | Z42: =VLOOKUP(D42,원가정보3!$E$5:$K$1048576,5,0) -> 378.4 | AA42: =Z42*O42 -> 3784
...

Sheet WBST
B2: WBST
D3: 수배관련 203339L01현장 참고하여 작성
A5: NO | B5: 변경 | C5: Level | D5: 공사/파트 번호 | E5: seq | F5: 버전 | G5: 공사/파트 명 | H5: G/L CODE | I5: 오더 | J5: 품목구분 | K5: Block No | L5: 내/외작 | M5: 사급 | N5: 수정 | O5: 수량 | P5: 공사수량 | Q5: 주석 | R5: 공사주석 | S5: 전용 | T5: SPEC | U5: SIZE | V5: 특별조달유형 | W5: 단위 | X5: BOM등록자 | Y5: BOM등록일 | Z5: BOM수정일 | AA5: 별도자재 | AB5: 단가 | AC5: 금액 | AD5: 합계
C6: 1 | D6: =IF('사양 입력'!$G$4="GD",VLOOKUP('사양 입력'!$G$4&'사양 입력'!$G$5&'사양 입력'!$G$6&'사양 입력'!$C$16&'사양 입력'!$G$12,'CP ASSY'!$U$12:$V$260,2,FALSE),"ERROR") -> ERROR | G6: CP ASSY (내작) | H6: =LEFT(D6,11) -> ERROR | O6: =IF(D6="ERROR","N/A",1) -> N/A | Q6: =VLOOKUP(D6,'[2]CP ASSY'!$D$12:$L$260,9,0) -> #N/A | X6: 조명석 | AB6: =VLOOKUP(D6,원가정보3!E5:I736,5,0) -> #N/A | AC6: =AB6*O6 -> #N/A | AD6: =SUMIF(AC6:AC118,"<>#n/a") -> 3828060.1 | AE6: 제어반 | AF6: =SUMIF(AC6:AC28,"<>#n/a") -> 633256.91
D7: =VLOOKUP($D$6,'CP ASSY'!$V$12:$AA$260,6,FALSE)&"00" -> #N/A | G7: CP ASSY (외주) | H7: =LEFT(D7,11) -> #N/A | O7: =IF('사양 입력'!G4="GD",1,"ERROR") -> ERROR | X7: 조명석 | AB7: =VLOOKUP(D7,원가정보3!E6:I737,5,0) -> #N/A | AC7: =AB7*O7 -> #N/A | AE7: 카탑 | AF7: =AC67 -> 358061
D8: 20400790G0200 | G8: USAF BOARD | H8: 20400790G02 | O8: 1 | X8: 조명석 | AB8: =VLOOKUP(D8,원가정보3!E7:I738,5,0) -> 56393 | AC8: =AB8*O8 -> 56393 | AE8: 의장보드 | AF8: =SUM(AC76:AC89) -> 517867
D9: 20400474G0400 | G9: UCMP BOARD ASSY | H9: 20400474G04 | O9: 1 | X9: 조명석 | AB9: =VLOOKUP(D9,원가정보3!E8:I739,5,0) -> #N/A | AC9: =AB9*O9 -> #N/A | AD9: 추가 20240125 | AE9: 케이블 | AF9: =SUM(AC33:AC56) -> 1561949.4
D10: =IF('사양 입력'!G14="EL TECH","20400641G0600",IF('사양 입력'!G14="SAFE TECH","20400641G0500",IF('사양 입력'!G14="MAJOR TECH","20400641G0800",IF('사양 입력'!G14="ROPE GRIPPER","20400641G0400")))) -> 20400641G0600 | G10: ROPE BRAKE OPT ASSY | H10: =LEFT(D10,11) -> 20400641G06 | O10: 1 | AB10: =VLOOKUP(D10,원가정보3!E9:I740,5,0) -> 48790 | AC10: =AB10*O10 -> 48790 | AD10: 추가 20240227 | AE10: 승강로부품 | AF10: =SUM(AC30:AC32)+SUM(AC57:AC66)+SUM(AC68:AC75) -> 657185.5
D11: 20400900G0500 | G11: VCON BOARD | H11: 20400900G05 | O11: 1 | X11: 조명석 | AB11: =VLOOKUP(D11,원가정보3!E10:I741,5,0) -> 30754 | AC11: =AB11*O11 -> 30754 | AE11: FLS | AF11: =AC29 -> 99740.295
D12: 20411025G0100 | G12: HHT-WB100N-SE ASSY | H12: 20411025G01 | O12: 1 | X12: 조명석 | AB12: =VLOOKUP(D12,원가정보3!E11:I742,5,0) -> 98455 | AC12: =AB12*O12 -> 98455 | AE12: 옵션 | AF12: =SUM(AC104:AC109) -> 0
D13: 259D0202G0500 | G13: GROUP CABLE | L13: 외작(ROH) | O13: =IF('사양 입력'!$G$10="2 CAR",1,0) -> 0 | Q13: 15 MR | X13: 조명석 | AB13: =VLOOKUP(D13,원가정보3!E12:I743,5,0) -> 18270 | AC13: =AB13*O13 -> 0
C14: 2 | D14: =IF($S$14=20,"HX062002H0900",IF($S$14=30,"HX062002H1000",IF($S$14=40,"HX062002H1100",IF($S$14=50,"HX062002H1200",IF($S$14=60,"HX062002H1300",IF($S$14=75,"HX062002H1400",FALSE)))))) -> HX062002H1000 | G14: MCCB | H14: =LEFT(D14,11) -> HX062002H10 | O14: 1 | R14: 전류 | S14: ='DROP DOWN 지정'!$AG$11 -> 30 | X14: 조명석 | AB14: =VLOOKUP(D14,원가정보3!E13:I744,5,0) -> 34510 | AC14: =AB14*O14 -> 34510
C15: 2 | D15: =IF('사양 입력'!$C$5<=11.3,"20410089G0600",IF(AND('사양 입력'!$C$5>11.3,'사양 입력'!$C$5<13),"20410089G0700",IF(AND('사양 입력'!$C$5>=13.1,'사양 입력'!$C$5<=14.1),"20410089G1000",IF(AND('사양 입력'!$C$5>=14.2,'사양 입력'!$C$5<=21),"20410089G0100",IF(AND('사양 입력'!$C$5>=21.1,'사양 입력'!$C$5<=26.5),"20410089G0800",IF(AND('사양 입력'!$C$5>=26.6,'사양 입력'!$C$5<=33),"20410089G0400","용량오류")))))) -> 20410089G0600 | G15: TERMINAL LUG | H15: =LEFT(D15,11) -> 20410089G06 | O15: 2 | X15: 조명석 | AB15: =VLOOKUP(D15,원가정보3!E14:I745,5,0) -> 7612 | AC15: =AB15*O15 -> 15224
C16: 2 | D16: =IF(AND('사양 입력'!$G$9="NO",'사양 입력'!$G$13="AC 220V"),"20401315G0200",IF(AND('사양 입력'!$G$9="NO",'사양 입력'!$G$13="AC 110V"),"20401315G1400",IF(AND('사양 입력'!$G$9="YES",'사양 입력'!$G$13="AC 220V"),"20401315G0300",IF(AND('사양 입력'!$G$9="YES",'사양 입력'!$G$13="AC 110V"),"20401315G1500",FALSE)))) -> 20401315G0200 | G16: TRANSFORMER | H16: =LEFT(D16,11) -> 20401315G02 | O16: 1 | X16: 조명석 | AB16: =VLOOKUP(D16,원가정보3!E15:I746,5,0) -> 90098 | AC16: =AB16*O16 -> 90098
C17: 2 | D17: HX001064H0400 | G17: CP NAME PLATE | H17: HX001064H04 | O17: 1 | X17: 조명석 | AB17: =VLOOKUP(D17,원가정보3!E16:I747,5,0) -> 339.416 | AC17: =AB17*O17 -> 339.416
C18: 2 | D18: 28500005G0100 | G18: LOAD SENSOR | H18: 28500005G01 | O18: 0 | X18: 조명석 | AB18: =VLOOKUP(D18,원가정보3!E17:I748,5,0) -> 13195 | AC18: =AB18*O18 -> 0
D19: 20410326G0200 | G19: BYPASS BUZZER | H19: 20410326G02 | I19: BUY | J19: 1 | K19: 244A | L19: 외작(ROH) | N19: 1 | O19: 1 | T19: WBVF, LOCATION=CAR BOTTOM | U19: 220 | W19: EA | X19: 조명석 | Y19: 45002.589 | Z19: 45002.589 | AB19: =VLOOKUP(D19,원가정보3!E18:I749,5,0) -> 12768 | AC19: =AB19*O19 -> 12768
D20: 20401397G3000 | E20: 680 | F20: 0 | G20: HALL PWR OPT ASSY | H20: 20401397G30 | I20: BUY | J20: 1 | K20: 204B20 | L20: 외작(roh) | O20: =IF('DROP DOWN 지정'!$X$35>3000,1,0) -> 0 | T20: UNDER 12A, BELOW 30FL | U20: WITH BOX | W20: EA | X20: 조명석 | AB20: =VLOOKUP(D20,원가정보3!E19:I750,5,0) -> 79170 | AC20: =AB20*O20 -> 0
D21: 20400955G0200 | E21: 600 | F21: 0 | G21: FR OPT ASSY | H21: 20400955G02 | I21: BUY | J21: 1 | K21: 204B08 | L21: 외작(roh) | O21: =IF('사양 입력'!$C$14>31000,1,0) -> 1 | T21: FOR EMERGENCY (EN81-A3) | X21: 조명석 | AB21: =VLOOKUP(D21,원가정보3!E20:I751,5,0) -> 20300 | AC21: =AB21*O21 -> 20300
D22: 20600093G0100 | E22: 1390 | F22: 0 | G22: PC BOARD | H22: 20600093G01 | I22: BUY | J22: 1 | K22: 206A | L22: 외작(roh) | O22: =O21 -> 1 | T22: ELD RST SENSING BOARD | X22: 조명석 | AB22: =VLOOKUP(D22,원가정보3!E21:I752,5,0) -> 6830 | AC22: =AB22*O22 -> 6830
D23: 20411328G0100 | G23: CP MANUAL | O23: 1 | AB23: =VLOOKUP(D23,원가정보3!E22:I753,5,0) -> 12078 | AC23: =AB23*O23 -> 12078 | AD23: 추가 20231101
D24: =REPLACE($D$25,9,1,"P") -> ERROR00P | G24: INVERTER (내작) | O24: 1 | X24: 조명석 | AB24: =VLOOKUP(D24,원가정보3!E23:I754,5,0) -> #N/A | AC24: =AB24*O24 -> #N/A
D25: =H25&"00" -> ERROR00 | G25: INVERTER (외주) | H25: =IF('사양 입력'!$G$4="GD",VLOOKUP('사양 입력'!$G$4&'사양 입력'!$G$5&'사양 입력'!$G$6&'사양 입력'!$C$16&'사양 입력'!$G$12,'CP ASSY'!$U$12:$Z$260,4,FALSE),"ERROR") -> ERROR | O25: 1 | Q25: =IF('사양 입력'!$G$4="GD",VLOOKUP('사양 입력'!$G$4&'사양 입력'!$G$5&'사양 입력'!$G$6&'사양 입력'!$C$16&'사양 입력'!$G$12,'CP ASSY'!$U$12:$Z$260,4,FALSE),"ERROR") -> ERROR | X25: 조명석 | AB25: =VLOOKUP(D25,원가정보3!E24:I755,5,0) -> #N/A | AC25: =AB25*O25 -> #N/A
D26: =H29&"00" -> 24110040G0300 | G26: PIM/IPM | H26: =LEFT(D26,11) -> 24110040G03 | O26: =IF('사양 입력'!$G$6="일반형",1,2) -> 1 | X26: 조명석 | AB26: =VLOOKUP(D26,원가정보3!E25:I756,5,0) -> 99740.295 | AC26: =AB26*O26 -> 99740.295 | AK26: =IF('사양 입력'!$G$4="GD",VLOOKUP('사양 입력'!$G$4&'사양 입력'!$G$5&'사양 입력'!$G$6&'사양 입력'!$C$16&'사양 입력'!$G$12,'CP ASSY'!$U$12:$Z$260,6,FALSE),"ERROR") -> ERROR
D27: 101C0537G0100 | G27: ENCODER | H27: 101C0537G01 | O27: 1 | X27: 조명석 | AB27: =VLOOKUP(D27,원가정보3!E26:I757,5,0) -> 75604.1 | AC27: =AB27*O27 -> 75604.1
D28: 20000126G0100 | G28: ENCODER COVER | H28: 20000126G01 | O28: 1 | X28: 조명석 | AB28: =VLOOKUP(D28,원가정보3!E27:I758,5,0) -> 31373.1 | AC28: =AB28*O28 -> 31373.1
A29: 37 | C29: 1 | D29: =IF('사양 입력'!$C$8=30,"24110040G0100",IF('사양 입력'!$C$8=45,"24110040G0200",IF('사양 입력'!$C$8=60,"24110040G0300",IF('사양 입력'!$C$8=90,"24110040G0400",IF('사양 입력'!$C$8=105,"24110040G0500",IF('사양 입력'!$C$8=120,"24110040G0600",IF('사양 입력'!$C$8=150,"24110040G0700",FALSE))))))) -> 24110040G0300 | E29: 160 | F29: 0 | G29: FLS ASSY | H29: =LEFT(D29,11) -> 24110040G03 | I29: BUY | J29: 1 | K29: 241A | L29: 외작(ROH) | O29: 1 | Q29: * KS 케이블 적용 | T29: 13K RAIL, 105M/MIN | U29: . | W29: EA | X29: 조명석 | Y29: 45001.746 | AB29: =VLOOKUP(D29,원가정보3!E26:I757,5,0) -> 99740.295 | AC29: =AB29*O29 -> 99740.295
A30: 264 | C30: 1 | D30: 24200129G0200 | E30: 1570 | F30: 0 | G30: LCD ASSY | H30: 24200129G02 | I30: BUY | J30: 1 | K30: 242A | L30: 외작(ROH) | O30: 1 | T30: WBLX, WBSS1 (RAIL TYPE) | U30: 4MR | W30: EA | X30: 조명석 | Y30: 44964.611 | AB30: =VLOOKUP(D30,원가정보3!E27:I758,5,0) -> 43654.6 | AC30: =AB30*O30 -> 43654.6
A31: 265 | C31: 1 | D31: 24200128G0200 | E31: 1580 | F31: 0 | G31: LCD VANE ASSY | H31: 24200128G02 | I31: BUY | J31: 1 | K31: 242A01 | L31: 외작(ROH) | O31: ='사양 입력'!C7 -> 15 | Q31: 8~18K RAIL | T31: STOP | U31: 13K,18K RAIL | W31: EA | X31: 조명석 | Y31: 44964.611 | AB31: =VLOOKUP(D31,원가정보3!E28:I759,5,0) -> 3390.2 | AC31: =AB31*O31 -> 50853
A32: 266 | C32: 1 | D32: 242C0130G0100 | E32: 1590 | F32: 0 | G32: BRACKET | H32: 242C0130G01 | I32: BUY | J32: 1 | K32: 242A02 | L32: 외작(ROH) | O32: =ROUNDUP(O31/5,0) -> 3 | T32: L=500MM | U32: . | W32: EA | X32: 조명석 | Y32: 44964.611 | AB32: =VLOOKUP(D32,원가정보3!E29:I760,5,0) -> 806.3 | AC32: =AB32*O32 -> 2418.9
A33: 40 | C33: 1 | D33: =IF('사양 입력'!C7<10,"25900933G0"&'사양 입력'!C7&"00","25900933G"&'사양 입력'!C7&"00") -> 25900933G1500 | E33: 190 | F33: 0 | G33: CABLE | H33: =LEFT(D33,11) -> 25900933G15 | I33: BUY | J33: 3 | K33: 259A | L33: 외작(ROH) | O33: 1 | Q33: * CP TO DUCT HOLE (SA) : 5250(MM) * HALL COM & INT HARNESS용 TT 값 : 9850 * TOTAL HEIGHT (TH) : 38150(MM) * TRAVEL HEIGHT (TR) : 31150(MM) * OVER HEAD (OH) : 5200(MM) * PIT (PIT) : 1800(MM) * 비상용 엘리베이터 : NO * HA (통신) = 3500mm로 제작 * HB (INTERLOCK) = 200mm로 제작 * T-CABLE HARNESS는 25900972G01을 따를 것 | T33: FIELD HARNESS CABLE (EN81-20/50) | U33: 11 | W33: EA | X33: 조명석 | Y33: 45001.746 | AB33: =VLOOKUP(D33,원가정보3!E30:I761,5,0) -> 131715.1 | AC33: =AB33*O33 -> 131715.1
A34: 41 | C34: 1 | D34: 25900888G0100 | E34: 200 | F34: 0 | G34: CABLE | H34: 25900888G01 | I34: BUY | J34: 3 | K34: 259A22 | L34: 외작(ROH) | O34: 1 | T34: FOR EN-20/50 | U34: . | W34: EA | X34: 조명석 | Y34: 45001.746 | AB34: =VLOOKUP(D34,원가정보3!E31:I762,5,0) -> 13311.1 | AC34: =AB34*O34 -> 13311.1
A35: 42 | C35: 1 | D35: 25900980G0900 | E35: 210 | F35: 0 | G35: CABLE ASSY | H35: 25900980G09 | I35: BUY | J35: 3 | K35: 259A22 | L35: 외작(ROH) | O35: 1 | T35: FOR PIT LAMP | U35: . | W35: EA | X35: 조명석 | Y35: 45001.746 | AB35: =VLOOKUP(D35,원가정보3!E32:I763,5,0) -> 3059.1 | AC35: =AB35*O35 -> 3059.1
D36: =IF('사양 입력'!G14="EL TECH","259C0168G0700",IF('사양 입력'!G14="SAFE TECH","259C0168G0800",IF('사양 입력'!G14="MAJOR TECH","259C0168G1500",IF('사양 입력'!G14="ROPE GRIPPER","259C0168G0600")))) -> 259C0168G0700 | G36: ROPE BRAKE CABLE HARNESS | H36: =LEFT(D36,11) -> 259C0168G07 | O36: 1 | AB36: =VLOOKUP(D36,원가정보3!E33:I764,5,0) -> #N/A | AD36: 추가 20240227
D37: 25900932G2000 | E37: 1600 | F37: 1 | G37: CABLE | H37: 25900932G20 | I37: BUY | J37: 3 | K37: 259A40 | L37: 외작(roh) | O37: =IF(O31<=20,O20,0) -> 0 | T37: OVER 3A, 1CORE | X37: 조명석 | AB37: =VLOOKUP(D37,원가정보3!E34:I765,5,0) -> 22330 | AC37: =AB37*O37 -> 0
D38: 25900932G3000 | E38: 1600 | F38: 1 | G38: CABLE | H38: 25900932G30 | I38: BUY | J38: 3 | K38: 259A40 | L38: 외작(roh) | O38: =IF(AND(O31>20,O31<30),O20,0) -> 0 | T38: OVER 3A, 1CORE | X38: 조명석 | AB38: =VLOOKUP(D38,원가정보3!E35:I766,5,0) -> 32378.5 | AC38: =AB38*O38 -> 0
A39: 43 | C39: 1 | D39: =IF('사양 입력'!$C$5<=7,"HX058004H0200",IF(AND('사양 입력'!$C$5>=7.1,'사양 입력'!$C$5<=11.3),"HX058004H0300",IF(AND('사양 입력'!$C$5>=11.4,'사양 입력'!$C$5<=14.1),"HX058004H0400",IF(AND('사양 입력'!$C$5>=14.2,'사양 입력'!$C$5<=20.6),"HX058004H0500",IF(AND('사양 입력'!$C$5>=20.7,'사양 입력'!$C$5<=26.5),"HX058004H0600",IF(AND('사양 입력'!$C$5>=26.6,'사양 입력'!$C$5<=33),"HX058004H0700",IF(AND('사양 입력'!$C$5>=33.1,'사양 입력'!$C$5<=50),"HX058004H0800","용량오류"))))))) -> HX058004H0200 | E39: 220 | F39: 0 | G39: POWER CABLE | H39: =LEFT(D39,11) -> HX058004H02 | I39: BUY | J39: 3 | K39: 259B01 | L39: 외작(ROH) | O39: 54 | Q39: POWER TO CP - 3 CORE 27 CP TO MOTOR - 3 CORE 27 | T39: KIV 16.0MMSQx1C, BLACK | U39: 750V, 70℃ | W39: M | X39: 조명석 | Y39: 45001.746 | AB39: =VLOOKUP(D39,원가정보3!E36:I767,5,0) -> 1027.4 | AC39: =AB39*O39 -> 55479.6
A40: 44 | C40: 1 | D40: =IF('사양 입력'!$C$5<=7,"HX058006H0200",IF(AND('사양 입력'!$C$5>=7.1,'사양 입력'!$C$5<=11.3),"HX058006H0300",IF(AND('사양 입력'!$C$5>=11.4,'사양 입력'!$C$5<=14.1),"HX058006H0400",IF(AND('사양 입력'!$C$5>=14.2,'사양 입력'!$C$5<=33),"HX058006H0500",IF(AND('사양 입력'!$C$5>=33.1,'사양 입력'!$C$5<=50),"HX058006H0600","용량오류"))))) -> HX058006H0200 | E40: 230 | F40: 1 | G40: CABLE | H40: =LEFT(D40,11) -> HX058006H02 | I40: BUY | J40: 3 | K40: 259B02 | L40: 외작(ROH) | O40: 18 | Q40: POWER TO CP - 1 CORE 9 CP TO MOTOR - 1 CORE 9 | T40: KIV 16SQ(GREEN-YELLOW) | U40: 750V, 70℃ | W40: M | X40: 조명석 | Y40: 45001.746 | AB40: =VLOOKUP(D40,원가정보3!E37:I768,5,0) -> 1027.4 | AC40: =AB40*O40 -> 18493.2
A41: 45 | C41: 1 | D41: HX058004H0100 | E41: 240 | F41: 0 | G41: LIGHTING CABLE | H41: HX058004H01 | I41: BUY | J41: 3 | K41: 259B03 | L41: 외작(ROH) | O41: 20 | Q41: POWER TO CP - 2 CORE 20 | T41: KIV 2.5MMSQx1C, BLACK | U41: 750V, 70℃ | W41: M | X41: 조명석 | Y41: 45001.746 | AB41: =VLOOKUP(D41,원가정보3!E38:I769,5,0) -> 671 | AC41: =AB41*O41 -> 13420
A42: 46 | C42: 1 | D42: HX058017H0100 | E42: 250 | F42: 0 | G42: CABLE | H42: HX058017H01 | I42: BUY | J42: 3 | K42: 259B04 | L42: 외작(ROH) | O42: 10 | Q42: FOR T-CABLE BINDING | T42: IV 2.0SQ,BLUE | U42: . | W42: M | X42: 조명석 | Y42: 45001.746 | AB42: =VLOOKUP(D42,원가정보3!E39:I770,5,0) -> 378.4 | AC42: =AB42*O42 -> 3784
...

Sheet 원가정보3
A1: □ 원가정보
I2: 세븐엠 | J2: 기타 | M2: 단가차이율 | N2: =M731/H731 -> 0 | P2: *간접비는 출하 완료 후 정산하여 현장마다 다르게 적용
H3: 추가적용율 | I3: 1 | J3: 1.1 | P3: 견적시 예상이 어려우므로 H열,I열 추가적용율로 견적 반영
A4: NO | B4: 옵션 BD | C4: 구분2 | D4: 세븐엠제작 | E4: 자재번호 | F4: 자재명 | G4: 사양 | H4: 원가 | I4: 적용원가 | J4: 비고 | L4: 20260812 단가 | M4: 단가차이 | N4: 차이율
A5: 1 | B5: CP | C5: CP ASSY | D5: Y | E5: 20410986G0100 | F5: WBLX-SE_ELD,STD INV,GI+PAINT | G5: CP WBLX-SE_ELD,STD INV,GI+PAINT 7.5kW | H5: 1561130 | I5: =IF(D5="Y",H5*$I$3,H5*$J$3) -> 1561130 | L5: =VLOOKUP(E5,[3]단가!B$4:M$724,12,0) -> 1561130 | M5: =L5-H5 -> 0 | N5: =M5/H5 -> 0
A6: 2 | B6: CP | C6: CP ASSY | D6: Y | E6: 20410986G0200 | F6: WBLX-SE_ELD,STD INV,GI+PAINT | G6: CP WBLX-SE_ELD,STD INV,GI+PAINT 11kW | H6: 1709655 | I6: =IF(D6="Y",H6*$I$3,H6*$J$3) -> 1709655 | L6: =VLOOKUP(E6,[3]단가!B$4:M$724,12,0) -> 1709655 | M6: =L6-H6 -> 0 | N6: =M6/H6 -> 0
A7: 3 | B7: CP | C7: CP ASSY | D7: Y | E7: 20410986G0300 | F7: WBLX-SE_ELD,STD INV,GI+PAINT | G7: CP WBLX-SE_ELD,STD INV,GI+PAINT 15kW | H7: 1957823 | I7: =IF(D7="Y",H7*$I$3,H7*$J$3) -> 1957823 | L7: =VLOOKUP(E7,[3]단가!B$4:M$724,12,0) -> 1957823 | M7: =L7-H7 -> 0 | N7: =M7/H7 -> 0
A8: 4 | B8: CP | C8: CP ASSY | D8: Y | E8: 20410986G0400 | F8: WBLX-SE_ELD,STD INV,GI+PAINT | G8: CP WBLX-SE_ELD,STD INV,GI+PAINT 22kW | H8: 2308079 | I8: =IF(D8="Y",H8*$I$3,H8*$J$3) -> 2308079 | L8: =VLOOKUP(E8,[3]단가!B$4:M$724,12,0) -> 2308079 | M8: =L8-H8 -> 0 | N8: =M8/H8 -> 0
A9: 5 | B9: CP | C9: CP ASSY | D9: Y | E9: 20410988G0100 | F9: WBSS-SE,STD INV,SUS,LH | G9: CP WBSS-SE,STD INV,SUS,LH 7.5kW,HH=2100 | H9: 667870 | I9: =IF(D9="Y",H9*$I$3,H9*$J$3) -> 667870 | L9: =VLOOKUP(E9,[3]단가!B$4:M$724,12,0) -> 667870 | M9: =L9-H9 -> 0 | N9: =M9/H9 -> 0
A10: 6 | B10: CP | C10: CP ASSY | D10: Y | E10: 20410988G0200 | F10: WBSS-SE,STD INV,SUS,LH | G10: CP WBSS-SE,STD INV,SUS,LH 11kW,HH=2100 | H10: 680050 | I10: =IF(D10="Y",H10*$I$3,H10*$J$3) -> 680050 | L10: =VLOOKUP(E10,[3]단가!B$4:M$724,12,0) -> 680050 | M10: =L10-H10 -> 0 | N10: =M10/H10 -> 0
A11: 7 | B11: CP | C11: CP ASSY | D11: Y | E11: 20410988G0300 | F11: WBSS-SE,STD INV,SUS,LH | G11: CP WBSS-SE,STD INV,SUS,LH 15kW,HH=2100 | H11: 693245 | I11: =IF(D11="Y",H11*$I$3,H11*$J$3) -> 693245 | L11: =VLOOKUP(E11,[3]단가!B$4:M$724,12,0) -> 693245 | M11: =L11-H11 -> 0 | N11: =M11/H11 -> 0
A12: 8 | B12: CP | C12: CP ASSY | D12: Y | E12: 20410988G0400 | F12: WBSS-SE,STD INV,SUS,LH | G12: CP WBSS-SE,STD INV,SUS,LH 22kW,HH=2100 | H12: 1117515 | I12: =IF(D12="Y",H12*$I$3,H12*$J$3) -> 1117515 | L12: =VLOOKUP(E12,[3]단가!B$4:M$724,12,0) -> 1117515 | M12: =L12-H12 -> 0 | N12: =M12/H12 -> 0
A13: 9 | B13: CP | C13: CP ASSY | D13: Y | E13: 20410988G0600 | F13: WBSS-SE,STD INV,SUS,LH | G13: CP WBSS-SE,STD INV,SUS,LH 7.5kW,HH=2200 | H13: 667870 | I13: =IF(D13="Y",H13*$I$3,H13*$J$3) -> 667870 | L13: =VLOOKUP(E13,[3]단가!B$4:M$724,12,0) -> 667870 | M13: =L13-H13 -> 0 | N13: =M13/H13 -> 0
A14: 10 | B14: CP | C14: CP ASSY | D14: Y | E14: 20410988G0700 | F14: WBSS-SE,STD INV,SUS,LH | G14: CP WBSS-SE,STD INV,SUS,LH 11kW,HH=2200 | H14: 680050 | I14: =IF(D14="Y",H14*$I$3,H14*$J$3) -> 680050 | L14: =VLOOKUP(E14,[3]단가!B$4:M$724,12,0) -> 680050 | M14: =L14-H14 -> 0 | N14: =M14/H14 -> 0
A15: 11 | B15: CP | C15: CP ASSY | D15: Y | E15: 20410988G0800 | F15: WBSS-SE,STD INV,SUS,LH | G15: CP WBSS-SE,STD INV,SUS,LH 15kW,HH=2200 | H15: 693245 | I15: =IF(D15="Y",H15*$I$3,H15*$J$3) -> 693245 | L15: =VLOOKUP(E15,[3]단가!B$4:M$724,12,0) -> 693245 | M15: =L15-H15 -> 0 | N15: =M15/H15 -> 0
A16: 12 | B16: CP | C16: CP ASSY | D16: Y | E16: 20410988G0900 | F16: WBSS-SE,STD INV,SUS,LH | G16: CP WBSS-SE,STD INV,SUS,LH 22kW,HH=2200 | H16: 1117515 | I16: =IF(D16="Y",H16*$I$3,H16*$J$3) -> 1117515 | L16: =VLOOKUP(E16,[3]단가!B$4:M$724,12,0) -> 1117515 | M16: =L16-H16 -> 0 | N16: =M16/H16 -> 0
... A124: 120 | B124: CP | C124: CP ASSY | D124: Y | E124: 20411108G2400 | F124: WBSS-SE,PWM INV,SUS(DOOR),RH | G124: CP WBSS-SE,PWM INV,SUS(DOOR),RH 22kW,HH= | H124: 2031319 | I124: =IF(D124="Y",H124*$I$3,H124*$J$3) -> 2031319 | L124: =VLOOKUP(E124,[3]단가!B$4:M$724,12,0) -> 2031319 | M124: =L124-H124 -> 0 | N124: =M124/H124 -> 0
A125: 121 | B125: CP | C125: CP CABINET | D125: N | E125: 20411047G0100 | F125: WBSS-SE,STD INV,SUSHL_304,LH | G125: CP CABINET WBSS-SE,STD INV,SUSHL_304,LH | H125: 455735 | I125: =IF(D125="Y",H125*$I$3,H125*$J$3) -> 501308.5 | L125: 455735 | M125: =L125-H125 -> 0 | N125: =M125/H125 -> 0
A126: 122 | B126: CP | C126: CP CABINET | D126: N | E126: 20411047G0200 | F126: WBSS-SE,STD INV,SUSHL_304,LH | G126: CP CABINET WBSS-SE,STD INV,SUSHL_304,LH | H126: 466900 | I126: =IF(D126="Y",H126*$I$3,H126*$J$3) -> 513590 | L126: 466900 | M126: =L126-H126 -> 0 | N126: =M126/H126 -> 0
A127: 123 | B127: CP | C127: CP CABINET | D127: N | E127: 20411047G0300 | F127: WBSS-SE,STD INV,SUSHL_304,LH | G127: CP CABINET WBSS-SE,STD INV,SUSHL_304,LH | H127: 482125 | I127: =IF(D127="Y",H127*$I$3,H127*$J$3) -> 530337.5 | L127: 482125 | M127: =L127-H127 -> 0 | N127: =M127/H127 -> 0
A128: 124 | B128: CP | C128: CP CABINET | D128: N | E128: 20411047G0400 | F128: WBSS-SE,STD INV,SUSHL_304,RH | G128: CP CABINET WBSS-SE,STD INV,SUSHL_304,RH | H128: 455735 | I128: =IF(D128="Y",H128*$I$3,H128*$J$3) -> 501308.5 | L128: 455735 | M128: =L128-H128 -> 0 | N128: =M128/H128 -> 0
A129: 125 | B129: CP | C129: CP CABINET | D129: N | E129: 20411047G0500 | F129: WBSS-SE,STD INV,SUSHL_304,RH | G129: CP CABINET WBSS-SE,STD INV,SUSHL_304,RH | H129: 466900 | I129: =IF(D129="Y",H129*$I$3,H129*$J$3) -> 513590 | L129: 466900 | M129: =L129-H129 -> 0 | N129: =M129/H129 -> 0
A130: 126 | B130: CP | C130: CP CABINET | D130: N | E130: 20411047G0600 | F130: WBSS-SE,STD INV,SUSHL_304,RH | G130: CP CABINET WBSS-SE,STD INV,SUSHL_304,RH | H130: 482125 | I130: =IF(D130="Y",H130*$I$3,H130*$J$3) -> 530337.5 | L130: 482125 | M130: =L130-H130 -> 0 | N130: =M130/H130 -> 0
A131: 127 | B131: CP | C131: CP CABINET | D131: Y | E131: 20411047G0700 | F131: WBSS-SE,STD INV,HOISTWAY | G131: CP CABINET WBSS-SE,STD INV,HOISTWAY 7.5~ | H131: 228781 | I131: =IF(D131="Y",H131*$I$3,H131*$J$3) -> 228781 | L131: =VLOOKUP(E131,[3]단가!B$4:M$724,12,0) -> 228781 | M131: =L131-H131 -> 0 | N131: =M131/H131 -> 0
A132: 128 | B132: CP | C132: CP CABINET | D132: N | E132: 20411048G0100 | F132: WBSS-SE,STD INV,SUSHL_304,LH | G132: CP CABINET WBSS-SE,STD INV,SUSHL_304,LH | H132: 547085 | I132: =IF(D132="Y",H132*$I$3,H132*$J$3) -> 601793.5 | L132: 547085 | M132: =L132-H132 -> 0 | N132: =M132/H132 -> 0
A133: 129 | B133: CP | C133: CP CABINET | D133: N | E133: 20411048G0200 | F133: WBSS-SE,STD INV,SUSHL_304,LH | G133: CP CABINET WBSS-SE,STD INV,SUSHL_304,LH | H133: 558250 | I133: =IF(D133="Y",H133*$I$3,H133*$J$3) -> 614075 | L133: 558250 | M133: =L133-H133 -> 0 | N133: =M133/H133 -> 0
A134: 130 | B134: CP | C134: CP CABINET | D134: N | E134: 20411048G0300 | F134: WBSS-SE,STD INV,SUSHL_304,LH | G134: CP CABINET WBSS-SE,STD INV,SUSHL_304,LH | H134: 569415 | I134: =IF(D134="Y",H134*$I$3,H134*$J$3) -> 626356.5 | L134: 569415 | M134: =L134-H134 -> 0 | N134: =M134/H134 -> 0
A135: 131 | B135: CP | C135: CP CABINET | D135: N | E135: 20411048G0400 | F135: WBSS-SE,STD INV,SUSHL_304,RH | G135: CP CABINET WBSS-SE,STD INV,SUSHL_304,RH | H135: 547085 | I135: =IF(D135="Y",H135*$I$3,H135*$J$3) -> 601793.5 | L135: 547085 | M135: =L135-H135 -> 0 | N135: =M135/H135 -> 0
A136: 132 | B136: CP | C136: CP CABINET | D136: N | E136: 20411048G0500 | F136: WBSS-SE,STD INV,SUSHL_304,RH | G136: CP CABINET WBSS-SE,STD INV,SUSHL_304,RH | H136: 558250 | I136: =IF(D136="Y",H136*$I$3,H136*$J$3) -> 614075 | L136: 558250 | M136: =L136-H136 -> 0 | N136: =M136/H136 -> 0
A137: 133 | B137: CP | C137: CP CABINET | D137: N | E137: 20411048G0600 | F137: WBSS-SE,STD INV,SUSHL_304,RH | G137: CP CABINET WBSS-SE,STD INV,SUSHL_304,RH | H137: 569415 | I137: =IF(D137="Y",H137*$I$3,H137*$J$3) -> 626356.5 | L137: 569415 | M137: =L137-H137 -> 0 | N137: =M137/H137 -> 0
A138: 134 | B138: CP | C138: CP CABINET | D138: Y | E138: 20411048G0700 | F138: WBSS-SE,STD INV,HOISTWAY | G138: CP CABINET WBSS-SE,STD INV,HOISTWAY 22kW | H138: 416759 | I138: =IF(D138="Y",H138*$I$3,H138*$J$3) -> 416759 | L138: =VLOOKUP(E138,[3]단가!B$4:M$724,12,0) -> 416759 | M138: =L138-H138 -> 0 | N138: =M138/H138 -> 0
A139: 135 | B139: CP | C139: CP CABINET | D139: N | E139: 20411050G0100 | F139: WBSS-SE,PWM INV,SUSHL_304,LH | G139: CP CABINET WBSS-SE,PWM INV,SUSHL_304,LH | H139: 455735 | I139: =IF(D139="Y",H139*$I$3,H139*$J$3) -> 501308.5 | L139: 455735 | M139: =L139-H139 -> 0 | N139: =M139/H139 -> 0
A140: 136 | B140: CP | C140: CP CABINET | D140: N | E140: 20411050G0200 | F140: WBSS-SE,PWM INV,SUSHL_304,LH | G140: CP CABINET WBSS-SE,PWM INV,SUSHL_304,LH | H140: 466900 | I140: =IF(D140="Y",H140*$I$3,H140*$J$3) -> 513590 | L140: 466900 | M140: =L140-H140 -> 0 | N140: =M140/H140 -> 0
A141: 137 | B141: CP | C141: CP CABINET | D141: N | E141: 20411050G0300 | F141: WBSS-SE,PWM INV,SUSHL_304,LH | G141: CP CABINET WBSS-SE,PWM INV,SUSHL_304,LH | H141: 482125 | I141: =IF(D141="Y",H141*$I$3,H141*$J$3) -> 530337.5 | L141: 482125 | M141: =L141-H141 -> 0 | N141: =M141/H141 -> 0
A142: 138 | B142: CP | C142: CP CABINET | D142: N | E142: 20411050G0400 | F142: WBSS-SE,PWM INV,SUSHL_304,RH | G142: CP CABINET WBSS-SE,PWM INV,SUSHL_304,RH | H142: 455735 | I142: =IF(D142="Y",H142*$I$3,H142*$J$3) -> 501308.5 | L142: 455735 | M142: =L142-H142 -> 0 | N142: =M142/H142 -> 0
A143: 139 | B143: CP | C143: CP CABINET | D143: N | E143: 20411050G0500 | F143: WBSS-SE,PWM INV,SUSHL_304,RH | G143: CP CABINET WBSS-SE,PWM INV,SUSHL_304,RH | H143: 466900 | I143: =IF(D143="Y",H143*$I$3,H143*$J$3) -> 513590 | L143: 466900 | M143: =L143-H143 -> 0 | N143: =M143/H143 -> 0
A144: 140 | B144: CP | C144: CP CABINET | D144: N | E144: 20411050G0600 | F144: WBSS-SE,PWM INV,SUSHL_304,RH | G144: CP CABINET WBSS-SE,PWM INV,SUSHL_304,RH | H144: 482125 | I144: =IF(D144="Y",H144*$I$3,H144*$J$3) -> 530337.5 | L144: 482125 | M144: =L144-H144 -> 0 | N144: =M144/H144 -> 0
A145: 141 | B145: CP | C145: CP CABINET | D145: Y | E145: 20411050G0700 | F145: WBSS-SE,PWM INV,HOISTWAY | G145: CP CABINET WBSS-SE,PWM INV,HOISTWAY 7.5~ | H145: 228781 | I145: =IF(D145="Y",H145*$I$3,H145*$J$3) -> 228781 | L145: =VLOOKUP(E145,[3]단가!B$4:M$724,12,0) -> 228781 | M145: =L145-H145 -> 0 | N145: =M145/H145 -> 0
A146: 142 | B146: CP | C146: CP CABINET | D146: N | E146: 20411051G0100 | F146: WBSS-SE,PWM INV,SUSHL_304,LH | G146: CP CABINET WBSS-SE,PWM INV,SUSHL_304,LH | H146: 455735 | I146: =IF(D146="Y",H146*$I$3,H146*$J$3) -> 501308.5 | L146: 455735 | M146: =L146-H146 -> 0 | N146: =M146/H146 -> 0
A147: 143 | B147: CP | C147: CP CABINET | D147: N | E147: 20411051G0200 | F147: WBSS-SE,PWM INV,SUSHL_304,LH | G147: CP CABINET WBSS-SE,PWM INV,SUSHL_304,LH | H147: 466900 | I147: =IF(D147="Y",H147*$I$3,H147*$J$3) -> 513590 | L147: 466900 | M147: =L147-H147 -> 0 | N147: =M147/H147 -> 0
...

Sheet DROP DOWN 지정
B2: 층수 | D2: 속도 | F2: 용량 | H2: 인승 | J2: 재질 | L2: MRL | N2: INVERTER 타입 | P2: 출입구 높이 | R2: 관통형 | T2: 장애인용 | V2: GROUP 운전 | X2: MRL 도어 방향 | Z2: 운송지역 | AB2: 비상통화장치 당사 적용 | AD2: JOB SITE TOOL | AF2: T-CABLE 사양 | AH2: CCTV CABLE | AJ2: AIRCON CABLE | AL2: MRL
B3: 2 | D3: 60 | F3: 550 | H3: MR | J3: GI+PAINT | L3: ALL SUS-HL | N3: 일반형 | P3: 2100 | R3: YES | T3: YES | V3: NO | X3: LEFT HINGE | Z3: 서울 | AB3: Y | AD3: Y | AF3: 표준형 | AH3: RG59 | AJ3: N
B4: 3 | D4: 90 | F4: 600 | H4: MRL | J4: GI | L4: DOOR만 SUS-HL | N4: 회생형 | P4: 2200 | R4: NO | T4: NO | V4: 2 CAR | X4: RIGHT HINGE | Z4: 충청 | AB4: N | AD4: N | AF4: UTP 내장형 | AH4: UTP | AJ4: 별도형 | AL4: 속도 | AM4: OVERHEAD | AN4: PIT
B5: 4 | D5: 105 | F5: 700 | H5: GD | J5: ALL SUS-HL | P5: 2400 | V5: 3 CAR 별도 문의 | Z5: 경기 | AF5: A/C 동력선 내장형 | AH5: RG59+CLIP | AL5: 60 | AM5: 4200 | AN5: 1200
B6: 5 | D6: 120 | F6: 750 | J6: DOOR만 SUS-HL | Z6: 경상 | AH6: UTP+CLIP | AL6: 90 | AM6: 4400 | AN6: 1350
B7: 6 | D7: 150 | F7: 900 | J7: GD | Z7: 호남 | AH7: N | AL7: 105 | AM7: 4500 | AN7: 1350
B8: 7 | F8: 1000 | J8: GI+PAINT | L8: ROPE BRAKE | N8: ENCODER 타입 | Z8: 강원 | AC8: K1 : | AD8: =IF(AND('DROP DOWN 지정'!$C$8<=150,'DROP DOWN 지정'!$C$6<=50),1.25,1.1) -> 1.25 | AL8: 120 | AM8: 4550 | AN8: 2050
B9: 8 | F9: 1150 | J9: GI | L9: EL TECH | N9: SINCOS | Z9: 제주 | AC9: Ic : | AD9: =IF('DROP DOWN 지정'!$C$8<=120,1,4) -> 1 | AL9: 150 | AM9: 4800 | AN9: 2200
B10: 9 | F10: 1200 | L10: SAFE TECH | N10: INCREMENTAL | Z10: 착불(업체 배차 시)
B11: 10 | F11: 1350 | L11: MAJOR TECH | V11: HIP 선택 | X11: HPI 선택 | Z11: 차단기 용량 산정 | AB11: 소요전류 | AC11: Infb : | AD11: =$AD$8*('사양 입력'!$C$6*1+$AD$9*1) -> 21.25 | AF11: 차단기 용량 | AG11: =IF(AD11<=20,20,IF(AND(AD11>20,AD11<=30),30,IF(AND(AD11>30,AD11<=40),40,IF(AND(AD11>40,AD11<=50),50,IF(AND(AD11>50,AD11<=60),60,IF(AND(AD11>60,AD11<=75),75,FALSE)))))) -> 30
B12: 11 | F12: 1600 | L12: ROPE GRIPPER | V12: HIP 원형 DOT | X12: HPI 원형 DOT
B13: 12 | F13: 1800 | V13: HIP 사각형 DOT | X13: HPI 사각형 DOT
B14: 13 | F14: 2000 | V14: HIP LCD | X14: HPI LCD | AL14: MR
B15: 14 | F15: 2500
B16: 15 | N16: 도어 전원 | AL16: 속도 | AM16: OVERHEAD | AN16: PIT
B17: 16 | N17: AC 220V | AL17: 60 | AM17: 4350 | AN17: 1250
B18: 17 | N18: AC 110V | V18: COP 선택 | X18: CPI 선택 | AL18: 90 | AM18: 4500 | AN18: 1400
B19: 18 | V19: COP 원형 DOT | X19: CPI 원형 DOT | AL19: 105 | AM19: 4550 | AN19: 1450
B20: 19 | V20: COP 사각형 DOT | X20: CPI 사각형 DOT | AL20: 120 | AM20: 4900 | AN20: 1900
B21: 20 | V21: COP LCD | X21: CPI LCD | AL21: 150 | AM21: 5300 | AN21: 2200
B22: 21 | V22: COP 인디게이터 미적용
B23: 22 | H23: 모터 전류
B24: 23 | H24: =IF('사양 입력'!$C$9>340,('사양 입력'!$C$9/340)*'사양 입력'!$C$6,'사양 입력'!$C$6) -> 16
B25: 24 | AL25: GD
B26: 25
B27: 26 | V27: 승장 부품 전류치 | W27: mA | AL27: 속도 | AM27: OVERHEAD | AN27: PIT
